WARNING:tensorflow:From ../disentanglement_lib/methods/unsupervised/train_partial.py:89: The name tf.gfile.IsDirectory is deprecated. Please use tf.io.gfile.isdir instead.

W0609 10:07:38.158151 140324213704512 deprecation_wrapper.py:119] From ../disentanglement_lib/methods/unsupervised/train_partial.py:89: The name tf.gfile.IsDirectory is deprecated. Please use tf.io.gfile.isdir instead.

WARNING:tensorflow:
The TensorFlow contrib module will not be included in TensorFlow 2.0.
For more information, please see:
  * https://github.com/tensorflow/community/blob/master/rfcs/20180907-contrib-sunset.md
  * https://github.com/tensorflow/addons
  * https://github.com/tensorflow/io (for I/O related ops)
If you depend on functionality not listed there, please file an issue.

W0609 10:07:44.102646 140324213704512 lazy_loader.py:50] 
The TensorFlow contrib module will not be included in TensorFlow 2.0.
For more information, please see:
  * https://github.com/tensorflow/community/blob/master/rfcs/20180907-contrib-sunset.md
  * https://github.com/tensorflow/addons
  * https://github.com/tensorflow/io (for I/O related ops)
If you depend on functionality not listed there, please file an issue.

WARNING:tensorflow:Estimator's model_fn (<bound method BaseVAE.model_fn of <disentanglement_lib.methods.unsupervised.vae.BetaVAE object at 0x7f9f73c58438>>) includes params argument, but params are not passed to Estimator.
W0609 10:07:44.103571 140324213704512 estimator.py:1984] Estimator's model_fn (<bound method BaseVAE.model_fn of <disentanglement_lib.methods.unsupervised.vae.BetaVAE object at 0x7f9f73c58438>>) includes params argument, but params are not passed to Estimator.
INFO:tensorflow:Using config: {'_model_dir': '3dshapes_models/vae3dshapes_model_s1000_1602/model/tf_checkpoint', '_tf_random_seed': 1602, '_save_summary_steps': 100, '_save_checkpoints_steps': None, '_save_checkpoints_secs': 600, '_session_config': allow_soft_placement: true
graph_options {
  rewrite_options {
    meta_optimizer_iterations: ONE
  }
}
, '_keep_checkpoint_max': 1, '_keep_checkpoint_every_n_hours': 10000, '_log_step_count_steps': None, '_train_distribute': None, '_device_fn': None, '_protocol': None, '_eval_distribute': None, '_experimental_distribute': None, '_experimental_max_worker_delay_secs': None, '_service': None, '_cluster_spec': <tensorflow.python.training.server_lib.ClusterSpec object at 0x7f9f4e0540f0>, '_task_type': 'worker', '_task_id': 0, '_global_id_in_cluster': 0, '_master': '', '_evaluation_master': '', '_is_chief': True, '_num_ps_replicas': 0, '_num_worker_replicas': 1, '_tpu_config': TPUConfig(iterations_per_loop=500, num_shards=None, num_cores_per_replica=None, per_host_input_for_training=2, tpu_job_name=None, initial_infeed_sleep_secs=None, input_partition_dims=None, eval_training_input_configuration=2), '_cluster': None}
I0609 10:07:44.105004 140324213704512 estimator.py:209] Using config: {'_model_dir': '3dshapes_models/vae3dshapes_model_s1000_1602/model/tf_checkpoint', '_tf_random_seed': 1602, '_save_summary_steps': 100, '_save_checkpoints_steps': None, '_save_checkpoints_secs': 600, '_session_config': allow_soft_placement: true
graph_options {
  rewrite_options {
    meta_optimizer_iterations: ONE
  }
}
, '_keep_checkpoint_max': 1, '_keep_checkpoint_every_n_hours': 10000, '_log_step_count_steps': None, '_train_distribute': None, '_device_fn': None, '_protocol': None, '_eval_distribute': None, '_experimental_distribute': None, '_experimental_max_worker_delay_secs': None, '_service': None, '_cluster_spec': <tensorflow.python.training.server_lib.ClusterSpec object at 0x7f9f4e0540f0>, '_task_type': 'worker', '_task_id': 0, '_global_id_in_cluster': 0, '_master': '', '_evaluation_master': '', '_is_chief': True, '_num_ps_replicas': 0, '_num_worker_replicas': 1, '_tpu_config': TPUConfig(iterations_per_loop=500, num_shards=None, num_cores_per_replica=None, per_host_input_for_training=2, tpu_job_name=None, initial_infeed_sleep_secs=None, input_partition_dims=None, eval_training_input_configuration=2), '_cluster': None}
INFO:tensorflow:_TPUContext: eval_on_tpu True
I0609 10:07:44.105360 140324213704512 tpu_context.py:209] _TPUContext: eval_on_tpu True
WARNING:tensorflow:eval_on_tpu ignored because use_tpu is False.
W0609 10:07:44.105530 140324213704512 tpu_context.py:211] eval_on_tpu ignored because use_tpu is False.
WARNING:tensorflow:From /Midgard/home/ppoklukar/anaconda3/lib/python3.7/site-packages/tensorflow/python/training/training_util.py:236: Variable.initialized_value (from tensorflow.python.ops.variables) is deprecated and will be removed in a future version.
Instructions for updating:
Use Variable.read_value. Variables in 2.X are initialized automatically both in eager and graph (inside tf.defun) contexts.
W0609 10:07:44.113412 140324213704512 deprecation.py:323] From /Midgard/home/ppoklukar/anaconda3/lib/python3.7/site-packages/tensorflow/python/training/training_util.py:236: Variable.initialized_value (from tensorflow.python.ops.variables) is deprecated and will be removed in a future version.
Instructions for updating:
Use Variable.read_value. Variables in 2.X are initialized automatically both in eager and graph (inside tf.defun) contexts.
WARNING:tensorflow:From /Midgard/home/ppoklukar/anaconda3/lib/python3.7/site-packages/tensorflow/python/data/ops/dataset_ops.py:494: py_func (from tensorflow.python.ops.script_ops) is deprecated and will be removed in a future version.
Instructions for updating:
tf.py_func is deprecated in TF V2. Instead, there are two
    options available in V2.
    - tf.py_function takes a python function which manipulates tf eager
    tensors instead of numpy arrays. It's easy to convert a tf eager tensor to
    an ndarray (just call tensor.numpy()) but having access to eager tensors
    means `tf.py_function`s can use accelerators such as GPUs as well as
    being differentiable using a gradient tape.
    - tf.numpy_function maintains the semantics of the deprecated tf.py_func
    (it is not differentiable, and manipulates numpy arrays). It drops the
    stateful argument making all functions stateful.
    
W0609 10:07:44.129389 140324213704512 deprecation.py:323] From /Midgard/home/ppoklukar/anaconda3/lib/python3.7/site-packages/tensorflow/python/data/ops/dataset_ops.py:494: py_func (from tensorflow.python.ops.script_ops) is deprecated and will be removed in a future version.
Instructions for updating:
tf.py_func is deprecated in TF V2. Instead, there are two
    options available in V2.
    - tf.py_function takes a python function which manipulates tf eager
    tensors instead of numpy arrays. It's easy to convert a tf eager tensor to
    an ndarray (just call tensor.numpy()) but having access to eager tensors
    means `tf.py_function`s can use accelerators such as GPUs as well as
    being differentiable using a gradient tape.
    - tf.numpy_function maintains the semantics of the deprecated tf.py_func
    (it is not differentiable, and manipulates numpy arrays). It drops the
    stateful argument making all functions stateful.
    
WARNING:tensorflow:From ../disentanglement_lib/methods/unsupervised/train_partial.py:155: DatasetV1.make_one_shot_iterator (from tensorflow.python.data.ops.dataset_ops) is deprecated and will be removed in a future version.
Instructions for updating:
Use `for ... in dataset:` to iterate over a dataset. If using `tf.estimator`, return the `Dataset` object directly from your input function. As a last resort, you can use `tf.compat.v1.data.make_one_shot_iterator(dataset)`.
W0609 10:07:44.149884 140324213704512 deprecation.py:323] From ../disentanglement_lib/methods/unsupervised/train_partial.py:155: DatasetV1.make_one_shot_iterator (from tensorflow.python.data.ops.dataset_ops) is deprecated and will be removed in a future version.
Instructions for updating:
Use `for ... in dataset:` to iterate over a dataset. If using `tf.estimator`, return the `Dataset` object directly from your input function. As a last resort, you can use `tf.compat.v1.data.make_one_shot_iterator(dataset)`.
INFO:tensorflow:Calling model_fn.
I0609 10:07:44.159074 140324213704512 estimator.py:1145] Calling model_fn.
INFO:tensorflow:Running train on CPU
I0609 10:07:44.159277 140324213704512 tpu_estimator.py:2965] Running train on CPU
WARNING:tensorflow:From ../disentanglement_lib/methods/shared/architectures.py:49: The name tf.variable_scope is deprecated. Please use tf.compat.v1.variable_scope instead.

W0609 10:07:44.159696 140324213704512 deprecation_wrapper.py:119] From ../disentanglement_lib/methods/shared/architectures.py:49: The name tf.variable_scope is deprecated. Please use tf.compat.v1.variable_scope instead.

WARNING:tensorflow:From ../disentanglement_lib/methods/shared/architectures.py:173: conv2d (from tensorflow.python.layers.convolutional) is deprecated and will be removed in a future version.
Instructions for updating:
Use `tf.keras.layers.Conv2D` instead.
W0609 10:07:44.159971 140324213704512 deprecation.py:323] From ../disentanglement_lib/methods/shared/architectures.py:173: conv2d (from tensorflow.python.layers.convolutional) is deprecated and will be removed in a future version.
Instructions for updating:
Use `tf.keras.layers.Conv2D` instead.
WARNING:tensorflow:From /Midgard/home/ppoklukar/anaconda3/lib/python3.7/site-packages/tensorflow/python/ops/init_ops.py:1251: calling VarianceScaling.__init__ (from tensorflow.python.ops.init_ops) with dtype is deprecated and will be removed in a future version.
Instructions for updating:
Call initializer instance with the dtype argument instead of passing it to the constructor
W0609 10:07:44.161377 140324213704512 deprecation.py:506] From /Midgard/home/ppoklukar/anaconda3/lib/python3.7/site-packages/tensorflow/python/ops/init_ops.py:1251: calling VarianceScaling.__init__ (from tensorflow.python.ops.init_ops) with dtype is deprecated and will be removed in a future version.
Instructions for updating:
Call initializer instance with the dtype argument instead of passing it to the constructor
WARNING:tensorflow:Entity <bound method Conv.call of <tensorflow.python.layers.convolutional.Conv2D object at 0x7f9f4d4149e8>> could not be transformed and will be executed as-is. Please report this to the AutgoGraph team. When filing the bug, set the verbosity to 10 (on Linux, `export AUTOGRAPH_VERBOSITY=10`) and attach the full output. Cause: converting <bound method Conv.call of <tensorflow.python.layers.convolutional.Conv2D object at 0x7f9f4d4149e8>>: AssertionError: Bad argument number for Name: 3, expecting 4
W0609 10:07:44.250864 140324213704512 ag_logging.py:145] Entity <bound method Conv.call of <tensorflow.python.layers.convolutional.Conv2D object at 0x7f9f4d4149e8>> could not be transformed and will be executed as-is. Please report this to the AutgoGraph team. When filing the bug, set the verbosity to 10 (on Linux, `export AUTOGRAPH_VERBOSITY=10`) and attach the full output. Cause: converting <bound method Conv.call of <tensorflow.python.layers.convolutional.Conv2D object at 0x7f9f4d4149e8>>: AssertionError: Bad argument number for Name: 3, expecting 4
WARNING:tensorflow:Entity <bound method Conv.call of <tensorflow.python.layers.convolutional.Conv2D object at 0x7f9f6d19a6d8>> could not be transformed and will be executed as-is. Please report this to the AutgoGraph team. When filing the bug, set the verbosity to 10 (on Linux, `export AUTOGRAPH_VERBOSITY=10`) and attach the full output. Cause: converting <bound method Conv.call of <tensorflow.python.layers.convolutional.Conv2D object at 0x7f9f6d19a6d8>>: AssertionError: Bad argument number for Name: 3, expecting 4
W0609 10:07:44.337713 140324213704512 ag_logging.py:145] Entity <bound method Conv.call of <tensorflow.python.layers.convolutional.Conv2D object at 0x7f9f6d19a6d8>> could not be transformed and will be executed as-is. Please report this to the AutgoGraph team. When filing the bug, set the verbosity to 10 (on Linux, `export AUTOGRAPH_VERBOSITY=10`) and attach the full output. Cause: converting <bound method Conv.call of <tensorflow.python.layers.convolutional.Conv2D object at 0x7f9f6d19a6d8>>: AssertionError: Bad argument number for Name: 3, expecting 4
WARNING:tensorflow:Entity <bound method Conv.call of <tensorflow.python.layers.convolutional.Conv2D object at 0x7f9f6d19a6d8>> could not be transformed and will be executed as-is. Please report this to the AutgoGraph team. When filing the bug, set the verbosity to 10 (on Linux, `export AUTOGRAPH_VERBOSITY=10`) and attach the full output. Cause: converting <bound method Conv.call of <tensorflow.python.layers.convolutional.Conv2D object at 0x7f9f6d19a6d8>>: AssertionError: Bad argument number for Name: 3, expecting 4
W0609 10:07:44.411631 140324213704512 ag_logging.py:145] Entity <bound method Conv.call of <tensorflow.python.layers.convolutional.Conv2D object at 0x7f9f6d19a6d8>> could not be transformed and will be executed as-is. Please report this to the AutgoGraph team. When filing the bug, set the verbosity to 10 (on Linux, `export AUTOGRAPH_VERBOSITY=10`) and attach the full output. Cause: converting <bound method Conv.call of <tensorflow.python.layers.convolutional.Conv2D object at 0x7f9f6d19a6d8>>: AssertionError: Bad argument number for Name: 3, expecting 4
WARNING:tensorflow:Entity <bound method Conv.call of <tensorflow.python.layers.convolutional.Conv2D object at 0x7f9f6d19a6d8>> could not be transformed and will be executed as-is. Please report this to the AutgoGraph team. When filing the bug, set the verbosity to 10 (on Linux, `export AUTOGRAPH_VERBOSITY=10`) and attach the full output. Cause: converting <bound method Conv.call of <tensorflow.python.layers.convolutional.Conv2D object at 0x7f9f6d19a6d8>>: AssertionError: Bad argument number for Name: 3, expecting 4
W0609 10:07:44.485817 140324213704512 ag_logging.py:145] Entity <bound method Conv.call of <tensorflow.python.layers.convolutional.Conv2D object at 0x7f9f6d19a6d8>> could not be transformed and will be executed as-is. Please report this to the AutgoGraph team. When filing the bug, set the verbosity to 10 (on Linux, `export AUTOGRAPH_VERBOSITY=10`) and attach the full output. Cause: converting <bound method Conv.call of <tensorflow.python.layers.convolutional.Conv2D object at 0x7f9f6d19a6d8>>: AssertionError: Bad argument number for Name: 3, expecting 4
WARNING:tensorflow:From ../disentanglement_lib/methods/shared/architectures.py:202: flatten (from tensorflow.python.layers.core) is deprecated and will be removed in a future version.
Instructions for updating:
Use keras.layers.flatten instead.
W0609 10:07:44.488889 140324213704512 deprecation.py:323] From ../disentanglement_lib/methods/shared/architectures.py:202: flatten (from tensorflow.python.layers.core) is deprecated and will be removed in a future version.
Instructions for updating:
Use keras.layers.flatten instead.
WARNING:tensorflow:Entity <bound method Flatten.call of <tensorflow.python.layers.core.Flatten object at 0x7f9f6d19a6d8>> could not be transformed and will be executed as-is. Please report this to the AutgoGraph team. When filing the bug, set the verbosity to 10 (on Linux, `export AUTOGRAPH_VERBOSITY=10`) and attach the full output. Cause: converting <bound method Flatten.call of <tensorflow.python.layers.core.Flatten object at 0x7f9f6d19a6d8>>: AttributeError: module 'gast' has no attribute 'Num'
W0609 10:07:44.502504 140324213704512 ag_logging.py:145] Entity <bound method Flatten.call of <tensorflow.python.layers.core.Flatten object at 0x7f9f6d19a6d8>> could not be transformed and will be executed as-is. Please report this to the AutgoGraph team. When filing the bug, set the verbosity to 10 (on Linux, `export AUTOGRAPH_VERBOSITY=10`) and attach the full output. Cause: converting <bound method Flatten.call of <tensorflow.python.layers.core.Flatten object at 0x7f9f6d19a6d8>>: AttributeError: module 'gast' has no attribute 'Num'
WARNING:tensorflow:From ../disentanglement_lib/methods/shared/architectures.py:203: dense (from tensorflow.python.layers.core) is deprecated and will be removed in a future version.
Instructions for updating:
Use keras.layers.dense instead.
W0609 10:07:44.504422 140324213704512 deprecation.py:323] From ../disentanglement_lib/methods/shared/architectures.py:203: dense (from tensorflow.python.layers.core) is deprecated and will be removed in a future version.
Instructions for updating:
Use keras.layers.dense instead.
WARNING:tensorflow:Entity <bound method Dense.call of <tensorflow.python.layers.core.Dense object at 0x7f9f6d19a6d8>> could not be transformed and will be executed as-is. Please report this to the AutgoGraph team. When filing the bug, set the verbosity to 10 (on Linux, `export AUTOGRAPH_VERBOSITY=10`) and attach the full output. Cause: converting <bound method Dense.call of <tensorflow.python.layers.core.Dense object at 0x7f9f6d19a6d8>>: AssertionError: Bad argument number for Name: 3, expecting 4
W0609 10:07:44.600047 140324213704512 ag_logging.py:145] Entity <bound method Dense.call of <tensorflow.python.layers.core.Dense object at 0x7f9f6d19a6d8>> could not be transformed and will be executed as-is. Please report this to the AutgoGraph team. When filing the bug, set the verbosity to 10 (on Linux, `export AUTOGRAPH_VERBOSITY=10`) and attach the full output. Cause: converting <bound method Dense.call of <tensorflow.python.layers.core.Dense object at 0x7f9f6d19a6d8>>: AssertionError: Bad argument number for Name: 3, expecting 4
WARNING:tensorflow:Entity <bound method Dense.call of <tensorflow.python.layers.core.Dense object at 0x7f9f6d19a6d8>> could not be transformed and will be executed as-is. Please report this to the AutgoGraph team. When filing the bug, set the verbosity to 10 (on Linux, `export AUTOGRAPH_VERBOSITY=10`) and attach the full output. Cause: converting <bound method Dense.call of <tensorflow.python.layers.core.Dense object at 0x7f9f6d19a6d8>>: AssertionError: Bad argument number for Name: 3, expecting 4
W0609 10:07:44.698882 140324213704512 ag_logging.py:145] Entity <bound method Dense.call of <tensorflow.python.layers.core.Dense object at 0x7f9f6d19a6d8>> could not be transformed and will be executed as-is. Please report this to the AutgoGraph team. When filing the bug, set the verbosity to 10 (on Linux, `export AUTOGRAPH_VERBOSITY=10`) and attach the full output. Cause: converting <bound method Dense.call of <tensorflow.python.layers.core.Dense object at 0x7f9f6d19a6d8>>: AssertionError: Bad argument number for Name: 3, expecting 4
WARNING:tensorflow:Entity <bound method Dense.call of <tensorflow.python.layers.core.Dense object at 0x7f9f6d19a6d8>> could not be transformed and will be executed as-is. Please report this to the AutgoGraph team. When filing the bug, set the verbosity to 10 (on Linux, `export AUTOGRAPH_VERBOSITY=10`) and attach the full output. Cause: converting <bound method Dense.call of <tensorflow.python.layers.core.Dense object at 0x7f9f6d19a6d8>>: AssertionError: Bad argument number for Name: 3, expecting 4
W0609 10:07:44.797852 140324213704512 ag_logging.py:145] Entity <bound method Dense.call of <tensorflow.python.layers.core.Dense object at 0x7f9f6d19a6d8>> could not be transformed and will be executed as-is. Please report this to the AutgoGraph team. When filing the bug, set the verbosity to 10 (on Linux, `export AUTOGRAPH_VERBOSITY=10`) and attach the full output. Cause: converting <bound method Dense.call of <tensorflow.python.layers.core.Dense object at 0x7f9f6d19a6d8>>: AssertionError: Bad argument number for Name: 3, expecting 4
WARNING:tensorflow:From ../disentanglement_lib/methods/unsupervised/gaussian_encoder_model.py:52: The name tf.random_normal is deprecated. Please use tf.random.normal instead.

W0609 10:07:44.801874 140324213704512 deprecation_wrapper.py:119] From ../disentanglement_lib/methods/unsupervised/gaussian_encoder_model.py:52: The name tf.random_normal is deprecated. Please use tf.random.normal instead.

WARNING:tensorflow:Entity <bound method Dense.call of <tensorflow.python.layers.core.Dense object at 0x7f9f4d414a58>> could not be transformed and will be executed as-is. Please report this to the AutgoGraph team. When filing the bug, set the verbosity to 10 (on Linux, `export AUTOGRAPH_VERBOSITY=10`) and attach the full output. Cause: converting <bound method Dense.call of <tensorflow.python.layers.core.Dense object at 0x7f9f4d414a58>>: AssertionError: Bad argument number for Name: 3, expecting 4
W0609 10:07:44.910401 140324213704512 ag_logging.py:145] Entity <bound method Dense.call of <tensorflow.python.layers.core.Dense object at 0x7f9f4d414a58>> could not be transformed and will be executed as-is. Please report this to the AutgoGraph team. When filing the bug, set the verbosity to 10 (on Linux, `export AUTOGRAPH_VERBOSITY=10`) and attach the full output. Cause: converting <bound method Dense.call of <tensorflow.python.layers.core.Dense object at 0x7f9f4d414a58>>: AssertionError: Bad argument number for Name: 3, expecting 4
WARNING:tensorflow:Entity <bound method Dense.call of <tensorflow.python.layers.core.Dense object at 0x7f9f4d414a58>> could not be transformed and will be executed as-is. Please report this to the AutgoGraph team. When filing the bug, set the verbosity to 10 (on Linux, `export AUTOGRAPH_VERBOSITY=10`) and attach the full output. Cause: converting <bound method Dense.call of <tensorflow.python.layers.core.Dense object at 0x7f9f4d414a58>>: AssertionError: Bad argument number for Name: 3, expecting 4
W0609 10:07:45.026035 140324213704512 ag_logging.py:145] Entity <bound method Dense.call of <tensorflow.python.layers.core.Dense object at 0x7f9f4d414a58>> could not be transformed and will be executed as-is. Please report this to the AutgoGraph team. When filing the bug, set the verbosity to 10 (on Linux, `export AUTOGRAPH_VERBOSITY=10`) and attach the full output. Cause: converting <bound method Dense.call of <tensorflow.python.layers.core.Dense object at 0x7f9f4d414a58>>: AssertionError: Bad argument number for Name: 3, expecting 4
WARNING:tensorflow:From ../disentanglement_lib/methods/shared/architectures.py:261: conv2d_transpose (from tensorflow.python.layers.convolutional) is deprecated and will be removed in a future version.
Instructions for updating:
Use `tf.keras.layers.Conv2DTranspose` instead.
W0609 10:07:45.030025 140324213704512 deprecation.py:323] From ../disentanglement_lib/methods/shared/architectures.py:261: conv2d_transpose (from tensorflow.python.layers.convolutional) is deprecated and will be removed in a future version.
Instructions for updating:
Use `tf.keras.layers.Conv2DTranspose` instead.
WARNING:tensorflow:Entity <bound method Conv2DTranspose.call of <tensorflow.python.layers.convolutional.Conv2DTranspose object at 0x7f9f4d414a58>> could not be transformed and will be executed as-is. Please report this to the AutgoGraph team. When filing the bug, set the verbosity to 10 (on Linux, `export AUTOGRAPH_VERBOSITY=10`) and attach the full output. Cause: converting <bound method Conv2DTranspose.call of <tensorflow.python.layers.convolutional.Conv2DTranspose object at 0x7f9f4d414a58>>: AttributeError: module 'gast' has no attribute 'Num'
W0609 10:07:45.061109 140324213704512 ag_logging.py:145] Entity <bound method Conv2DTranspose.call of <tensorflow.python.layers.convolutional.Conv2DTranspose object at 0x7f9f4d414a58>> could not be transformed and will be executed as-is. Please report this to the AutgoGraph team. When filing the bug, set the verbosity to 10 (on Linux, `export AUTOGRAPH_VERBOSITY=10`) and attach the full output. Cause: converting <bound method Conv2DTranspose.call of <tensorflow.python.layers.convolutional.Conv2DTranspose object at 0x7f9f4d414a58>>: AttributeError: module 'gast' has no attribute 'Num'
WARNING:tensorflow:Entity <bound method Conv2DTranspose.call of <tensorflow.python.layers.convolutional.Conv2DTranspose object at 0x7f9f4d414a58>> could not be transformed and will be executed as-is. Please report this to the AutgoGraph team. When filing the bug, set the verbosity to 10 (on Linux, `export AUTOGRAPH_VERBOSITY=10`) and attach the full output. Cause: converting <bound method Conv2DTranspose.call of <tensorflow.python.layers.convolutional.Conv2DTranspose object at 0x7f9f4d414a58>>: AttributeError: module 'gast' has no attribute 'Num'
W0609 10:07:45.248234 140324213704512 ag_logging.py:145] Entity <bound method Conv2DTranspose.call of <tensorflow.python.layers.convolutional.Conv2DTranspose object at 0x7f9f4d414a58>> could not be transformed and will be executed as-is. Please report this to the AutgoGraph team. When filing the bug, set the verbosity to 10 (on Linux, `export AUTOGRAPH_VERBOSITY=10`) and attach the full output. Cause: converting <bound method Conv2DTranspose.call of <tensorflow.python.layers.convolutional.Conv2DTranspose object at 0x7f9f4d414a58>>: AttributeError: module 'gast' has no attribute 'Num'
WARNING:tensorflow:Entity <bound method Conv2DTranspose.call of <tensorflow.python.layers.convolutional.Conv2DTranspose object at 0x7f9f4d414a58>> could not be transformed and will be executed as-is. Please report this to the AutgoGraph team. When filing the bug, set the verbosity to 10 (on Linux, `export AUTOGRAPH_VERBOSITY=10`) and attach the full output. Cause: converting <bound method Conv2DTranspose.call of <tensorflow.python.layers.convolutional.Conv2DTranspose object at 0x7f9f4d414a58>>: AttributeError: module 'gast' has no attribute 'Num'
W0609 10:07:45.297018 140324213704512 ag_logging.py:145] Entity <bound method Conv2DTranspose.call of <tensorflow.python.layers.convolutional.Conv2DTranspose object at 0x7f9f4d414a58>> could not be transformed and will be executed as-is. Please report this to the AutgoGraph team. When filing the bug, set the verbosity to 10 (on Linux, `export AUTOGRAPH_VERBOSITY=10`) and attach the full output. Cause: converting <bound method Conv2DTranspose.call of <tensorflow.python.layers.convolutional.Conv2DTranspose object at 0x7f9f4d414a58>>: AttributeError: module 'gast' has no attribute 'Num'
WARNING:tensorflow:Entity <bound method Conv2DTranspose.call of <tensorflow.python.layers.convolutional.Conv2DTranspose object at 0x7f9f4d414a58>> could not be transformed and will be executed as-is. Please report this to the AutgoGraph team. When filing the bug, set the verbosity to 10 (on Linux, `export AUTOGRAPH_VERBOSITY=10`) and attach the full output. Cause: converting <bound method Conv2DTranspose.call of <tensorflow.python.layers.convolutional.Conv2DTranspose object at 0x7f9f4d414a58>>: AttributeError: module 'gast' has no attribute 'Num'
W0609 10:07:45.346386 140324213704512 ag_logging.py:145] Entity <bound method Conv2DTranspose.call of <tensorflow.python.layers.convolutional.Conv2DTranspose object at 0x7f9f4d414a58>> could not be transformed and will be executed as-is. Please report this to the AutgoGraph team. When filing the bug, set the verbosity to 10 (on Linux, `export AUTOGRAPH_VERBOSITY=10`) and attach the full output. Cause: converting <bound method Conv2DTranspose.call of <tensorflow.python.layers.convolutional.Conv2DTranspose object at 0x7f9f4d414a58>>: AttributeError: module 'gast' has no attribute 'Num'
WARNING:tensorflow:From ../disentanglement_lib/methods/unsupervised/vae.py:54: The name tf.get_collection is deprecated. Please use tf.compat.v1.get_collection instead.

W0609 10:07:45.378381 140324213704512 deprecation_wrapper.py:119] From ../disentanglement_lib/methods/unsupervised/vae.py:54: The name tf.get_collection is deprecated. Please use tf.compat.v1.get_collection instead.

WARNING:tensorflow:From ../disentanglement_lib/methods/unsupervised/vae.py:54: The name tf.GraphKeys is deprecated. Please use tf.compat.v1.GraphKeys instead.

W0609 10:07:45.378584 140324213704512 deprecation_wrapper.py:119] From ../disentanglement_lib/methods/unsupervised/vae.py:54: The name tf.GraphKeys is deprecated. Please use tf.compat.v1.GraphKeys instead.

WARNING:tensorflow:From ../disentanglement_lib/methods/unsupervised/vae.py:56: The name tf.train.get_global_step is deprecated. Please use tf.compat.v1.train.get_global_step instead.

W0609 10:07:45.378703 140324213704512 deprecation_wrapper.py:119] From ../disentanglement_lib/methods/unsupervised/vae.py:56: The name tf.train.get_global_step is deprecated. Please use tf.compat.v1.train.get_global_step instead.

WARNING:tensorflow:From ../disentanglement_lib/methods/unsupervised/vae.py:58: The name tf.summary.scalar is deprecated. Please use tf.compat.v1.summary.scalar instead.

W0609 10:07:45.956184 140324213704512 deprecation_wrapper.py:119] From ../disentanglement_lib/methods/unsupervised/vae.py:58: The name tf.summary.scalar is deprecated. Please use tf.compat.v1.summary.scalar instead.

WARNING:tensorflow:From ../disentanglement_lib/methods/unsupervised/vae.py:61: The name tf.train.LoggingTensorHook is deprecated. Please use tf.estimator.LoggingTensorHook instead.

W0609 10:07:45.959337 140324213704512 deprecation_wrapper.py:119] From ../disentanglement_lib/methods/unsupervised/vae.py:61: The name tf.train.LoggingTensorHook is deprecated. Please use tf.estimator.LoggingTensorHook instead.

INFO:tensorflow:Done calling model_fn.
I0609 10:07:45.960454 140324213704512 estimator.py:1147] Done calling model_fn.
INFO:tensorflow:Create CheckpointSaverHook.
I0609 10:07:45.961870 140324213704512 basic_session_run_hooks.py:541] Create CheckpointSaverHook.
WARNING:tensorflow:From /Midgard/home/ppoklukar/anaconda3/lib/python3.7/site-packages/tensorflow/python/ops/array_ops.py:1354: add_dispatch_support.<locals>.wrapper (from tensorflow.python.ops.array_ops) is deprecated and will be removed in a future version.
Instructions for updating:
Use tf.where in 2.0, which has the same broadcast rule as np.where
W0609 10:07:46.281927 140324213704512 deprecation.py:323] From /Midgard/home/ppoklukar/anaconda3/lib/python3.7/site-packages/tensorflow/python/ops/array_ops.py:1354: add_dispatch_support.<locals>.wrapper (from tensorflow.python.ops.array_ops) is deprecated and will be removed in a future version.
Instructions for updating:
Use tf.where in 2.0, which has the same broadcast rule as np.where
INFO:tensorflow:Graph was finalized.
I0609 10:07:46.447886 140324213704512 monitored_session.py:240] Graph was finalized.
2020-06-09 10:07:46.448254: I tensorflow/core/platform/cpu_feature_guard.cc:142] Your CPU supports instructions that this TensorFlow binary was not compiled to use: AVX2 FMA
2020-06-09 10:07:46.505149: I tensorflow/core/platform/profile_utils/cpu_utils.cc:94] CPU Frequency: 2099990000 Hz
2020-06-09 10:07:46.505576: I tensorflow/compiler/xla/service/service.cc:168] XLA service 0x564ac18f0f80 executing computations on platform Host. Devices:
2020-06-09 10:07:46.505599: I tensorflow/compiler/xla/service/service.cc:175]   StreamExecutor device (0): <undefined>, <undefined>
2020-06-09 10:07:46.507548: I tensorflow/stream_executor/platform/default/dso_loader.cc:42] Successfully opened dynamic library libcuda.so.1
2020-06-09 10:07:46.532085: I tensorflow/core/common_runtime/gpu/gpu_device.cc:1640] Found device 0 with properties: 
name: GeForce GTX 1080 Ti major: 6 minor: 1 memoryClockRate(GHz): 1.62
pciBusID: 0000:81:00.0
2020-06-09 10:07:46.568579: I tensorflow/stream_executor/platform/default/dso_loader.cc:42] Successfully opened dynamic library libcudart.so.10.0
2020-06-09 10:07:46.824591: I tensorflow/stream_executor/platform/default/dso_loader.cc:42] Successfully opened dynamic library libcublas.so.10.0
2020-06-09 10:07:46.934397: I tensorflow/stream_executor/platform/default/dso_loader.cc:42] Successfully opened dynamic library libcufft.so.10.0
2020-06-09 10:07:47.120423: I tensorflow/stream_executor/platform/default/dso_loader.cc:42] Successfully opened dynamic library libcurand.so.10.0
2020-06-09 10:07:47.375166: I tensorflow/stream_executor/platform/default/dso_loader.cc:42] Successfully opened dynamic library libcusolver.so.10.0
2020-06-09 10:07:47.519878: I tensorflow/stream_executor/platform/default/dso_loader.cc:42] Successfully opened dynamic library libcusparse.so.10.0
2020-06-09 10:07:47.520712: I tensorflow/stream_executor/platform/default/dso_loader.cc:53] Could not dlopen library 'libcudnn.so.7'; dlerror: libcudnn.so.7: cannot open shared object file: No such file or directory
2020-06-09 10:07:47.520734: W tensorflow/core/common_runtime/gpu/gpu_device.cc:1663] Cannot dlopen some GPU libraries. Skipping registering GPU devices...
2020-06-09 10:07:47.677246: I tensorflow/core/common_runtime/gpu/gpu_device.cc:1181] Device interconnect StreamExecutor with strength 1 edge matrix:
2020-06-09 10:07:47.677292: I tensorflow/core/common_runtime/gpu/gpu_device.cc:1187]      0 
2020-06-09 10:07:47.677309: I tensorflow/core/common_runtime/gpu/gpu_device.cc:1200] 0:   N 
2020-06-09 10:07:47.681254: I tensorflow/compiler/xla/service/service.cc:168] XLA service 0x564ac27a9fa0 executing computations on platform CUDA. Devices:
2020-06-09 10:07:47.681276: I tensorflow/compiler/xla/service/service.cc:175]   StreamExecutor device (0): GeForce GTX 1080 Ti, Compute Capability 6.1
2020-06-09 10:07:47.858732: W tensorflow/compiler/jit/mark_for_compilation_pass.cc:1412] (One-time warning): Not using XLA:CPU for cluster because envvar TF_XLA_FLAGS=--tf_xla_cpu_global_jit was not set.  If you want XLA:CPU, either set that envvar, or use experimental_jit_scope to enable XLA:CPU.  To confirm that XLA is active, pass --vmodule=xla_compilation_cache=1 (as a proper command-line flag, not via TF_XLA_FLAGS) or set the envvar XLA_FLAGS=--xla_hlo_profile.
INFO:tensorflow:Running local_init_op.
I0609 10:07:48.009526 140324213704512 session_manager.py:500] Running local_init_op.
INFO:tensorflow:Done running local_init_op.
I0609 10:07:48.023497 140324213704512 session_manager.py:502] Done running local_init_op.
INFO:tensorflow:Saving checkpoints for 0 into 3dshapes_models/vae3dshapes_model_s1000_1602/model/tf_checkpoint/model.ckpt.
I0609 10:07:48.637119 140324213704512 basic_session_run_hooks.py:606] Saving checkpoints for 0 into 3dshapes_models/vae3dshapes_model_s1000_1602/model/tf_checkpoint/model.ckpt.
INFO:tensorflow:elbo = -1933.9756, loss = 1933.9756, reconstruction_loss = 1933.9291
I0609 10:07:49.509559 140324213704512 basic_session_run_hooks.py:262] elbo = -1933.9756, loss = 1933.9756, reconstruction_loss = 1933.9291
INFO:tensorflow:global_step/sec: 2.68386
I0609 10:07:49.882917 140324213704512 tpu_estimator.py:2159] global_step/sec: 2.68386
INFO:tensorflow:examples/sec: 171.767
I0609 10:07:49.883528 140324213704512 tpu_estimator.py:2160] examples/sec: 171.767
INFO:tensorflow:global_step/sec: 6.15889
I0609 10:07:50.045295 140324213704512 tpu_estimator.py:2159] global_step/sec: 6.15889
INFO:tensorflow:examples/sec: 394.169
I0609 10:07:50.045607 140324213704512 tpu_estimator.py:2160] examples/sec: 394.169
INFO:tensorflow:global_step/sec: 6.12502
I0609 10:07:50.208511 140324213704512 tpu_estimator.py:2159] global_step/sec: 6.12502
INFO:tensorflow:examples/sec: 392.001
I0609 10:07:50.208786 140324213704512 tpu_estimator.py:2160] examples/sec: 392.001
INFO:tensorflow:global_step/sec: 5.95745
I0609 10:07:50.376371 140324213704512 tpu_estimator.py:2159] global_step/sec: 5.95745
INFO:tensorflow:examples/sec: 381.277
I0609 10:07:50.376642 140324213704512 tpu_estimator.py:2160] examples/sec: 381.277
INFO:tensorflow:Saving checkpoints for 5 into 3dshapes_models/vae3dshapes_model_s1000_1602/model/tf_checkpoint/model.ckpt.
I0609 10:07:50.376997 140324213704512 basic_session_run_hooks.py:606] Saving checkpoints for 5 into 3dshapes_models/vae3dshapes_model_s1000_1602/model/tf_checkpoint/model.ckpt.
WARNING:tensorflow:From /Midgard/home/ppoklukar/anaconda3/lib/python3.7/site-packages/tensorflow/python/training/saver.py:960: remove_checkpoint (from tensorflow.python.training.checkpoint_management) is deprecated and will be removed in a future version.
Instructions for updating:
Use standard file APIs to delete files with this prefix.
W0609 10:07:50.470248 140324213704512 deprecation.py:323] From /Midgard/home/ppoklukar/anaconda3/lib/python3.7/site-packages/tensorflow/python/training/saver.py:960: remove_checkpoint (from tensorflow.python.training.checkpoint_management) is deprecated and will be removed in a future version.
Instructions for updating:
Use standard file APIs to delete files with this prefix.
INFO:tensorflow:Loss for final step: 1947.5784.
I0609 10:07:50.575365 140324213704512 estimator.py:368] Loss for final step: 1947.5784.
INFO:tensorflow:training_loop marked as finished
I0609 10:07:50.575940 140324213704512 error_handling.py:96] training_loop marked as finished
WARNING:tensorflow:From ../disentanglement_lib/methods/unsupervised/gaussian_encoder_model.py:74: The name tf.get_variable_scope is deprecated. Please use tf.compat.v1.get_variable_scope instead.

W0609 10:07:50.944362 140324213704512 deprecation_wrapper.py:119] From ../disentanglement_lib/methods/unsupervised/gaussian_encoder_model.py:74: The name tf.get_variable_scope is deprecated. Please use tf.compat.v1.get_variable_scope instead.

WARNING:tensorflow:Entity <bound method Conv.call of <tensorflow.python.layers.convolutional.Conv2D object at 0x7f9f4cbf2ef0>> could not be transformed and will be executed as-is. Please report this to the AutgoGraph team. When filing the bug, set the verbosity to 10 (on Linux, `export AUTOGRAPH_VERBOSITY=10`) and attach the full output. Cause: converting <bound method Conv.call of <tensorflow.python.layers.convolutional.Conv2D object at 0x7f9f4cbf2ef0>>: AssertionError: Bad argument number for Name: 3, expecting 4
W0609 10:07:51.026964 140324213704512 ag_logging.py:145] Entity <bound method Conv.call of <tensorflow.python.layers.convolutional.Conv2D object at 0x7f9f4cbf2ef0>> could not be transformed and will be executed as-is. Please report this to the AutgoGraph team. When filing the bug, set the verbosity to 10 (on Linux, `export AUTOGRAPH_VERBOSITY=10`) and attach the full output. Cause: converting <bound method Conv.call of <tensorflow.python.layers.convolutional.Conv2D object at 0x7f9f4cbf2ef0>>: AssertionError: Bad argument number for Name: 3, expecting 4
WARNING:tensorflow:Entity <bound method Conv.call of <tensorflow.python.layers.convolutional.Conv2D object at 0x7f9f4cbf2ef0>> could not be transformed and will be executed as-is. Please report this to the AutgoGraph team. When filing the bug, set the verbosity to 10 (on Linux, `export AUTOGRAPH_VERBOSITY=10`) and attach the full output. Cause: converting <bound method Conv.call of <tensorflow.python.layers.convolutional.Conv2D object at 0x7f9f4cbf2ef0>>: AssertionError: Bad argument number for Name: 3, expecting 4
W0609 10:07:51.103997 140324213704512 ag_logging.py:145] Entity <bound method Conv.call of <tensorflow.python.layers.convolutional.Conv2D object at 0x7f9f4cbf2ef0>> could not be transformed and will be executed as-is. Please report this to the AutgoGraph team. When filing the bug, set the verbosity to 10 (on Linux, `export AUTOGRAPH_VERBOSITY=10`) and attach the full output. Cause: converting <bound method Conv.call of <tensorflow.python.layers.convolutional.Conv2D object at 0x7f9f4cbf2ef0>>: AssertionError: Bad argument number for Name: 3, expecting 4
WARNING:tensorflow:Entity <bound method Conv.call of <tensorflow.python.layers.convolutional.Conv2D object at 0x7f9f4cbf2ef0>> could not be transformed and will be executed as-is. Please report this to the AutgoGraph team. When filing the bug, set the verbosity to 10 (on Linux, `export AUTOGRAPH_VERBOSITY=10`) and attach the full output. Cause: converting <bound method Conv.call of <tensorflow.python.layers.convolutional.Conv2D object at 0x7f9f4cbf2ef0>>: AssertionError: Bad argument number for Name: 3, expecting 4
W0609 10:07:51.180259 140324213704512 ag_logging.py:145] Entity <bound method Conv.call of <tensorflow.python.layers.convolutional.Conv2D object at 0x7f9f4cbf2ef0>> could not be transformed and will be executed as-is. Please report this to the AutgoGraph team. When filing the bug, set the verbosity to 10 (on Linux, `export AUTOGRAPH_VERBOSITY=10`) and attach the full output. Cause: converting <bound method Conv.call of <tensorflow.python.layers.convolutional.Conv2D object at 0x7f9f4cbf2ef0>>: AssertionError: Bad argument number for Name: 3, expecting 4
WARNING:tensorflow:Entity <bound method Conv.call of <tensorflow.python.layers.convolutional.Conv2D object at 0x7f9f4cbf2ef0>> could not be transformed and will be executed as-is. Please report this to the AutgoGraph team. When filing the bug, set the verbosity to 10 (on Linux, `export AUTOGRAPH_VERBOSITY=10`) and attach the full output. Cause: converting <bound method Conv.call of <tensorflow.python.layers.convolutional.Conv2D object at 0x7f9f4cbf2ef0>>: AssertionError: Bad argument number for Name: 3, expecting 4
W0609 10:07:51.255927 140324213704512 ag_logging.py:145] Entity <bound method Conv.call of <tensorflow.python.layers.convolutional.Conv2D object at 0x7f9f4cbf2ef0>> could not be transformed and will be executed as-is. Please report this to the AutgoGraph team. When filing the bug, set the verbosity to 10 (on Linux, `export AUTOGRAPH_VERBOSITY=10`) and attach the full output. Cause: converting <bound method Conv.call of <tensorflow.python.layers.convolutional.Conv2D object at 0x7f9f4cbf2ef0>>: AssertionError: Bad argument number for Name: 3, expecting 4
WARNING:tensorflow:Entity <bound method Flatten.call of <tensorflow.python.layers.core.Flatten object at 0x7f9f4cbf2ef0>> could not be transformed and will be executed as-is. Please report this to the AutgoGraph team. When filing the bug, set the verbosity to 10 (on Linux, `export AUTOGRAPH_VERBOSITY=10`) and attach the full output. Cause: converting <bound method Flatten.call of <tensorflow.python.layers.core.Flatten object at 0x7f9f4cbf2ef0>>: AttributeError: module 'gast' has no attribute 'Num'
W0609 10:07:51.272207 140324213704512 ag_logging.py:145] Entity <bound method Flatten.call of <tensorflow.python.layers.core.Flatten object at 0x7f9f4cbf2ef0>> could not be transformed and will be executed as-is. Please report this to the AutgoGraph team. When filing the bug, set the verbosity to 10 (on Linux, `export AUTOGRAPH_VERBOSITY=10`) and attach the full output. Cause: converting <bound method Flatten.call of <tensorflow.python.layers.core.Flatten object at 0x7f9f4cbf2ef0>>: AttributeError: module 'gast' has no attribute 'Num'
WARNING:tensorflow:Entity <bound method Dense.call of <tensorflow.python.layers.core.Dense object at 0x7f9f4cbf2ef0>> could not be transformed and will be executed as-is. Please report this to the AutgoGraph team. When filing the bug, set the verbosity to 10 (on Linux, `export AUTOGRAPH_VERBOSITY=10`) and attach the full output. Cause: converting <bound method Dense.call of <tensorflow.python.layers.core.Dense object at 0x7f9f4cbf2ef0>>: AssertionError: Bad argument number for Name: 3, expecting 4
W0609 10:07:51.371766 140324213704512 ag_logging.py:145] Entity <bound method Dense.call of <tensorflow.python.layers.core.Dense object at 0x7f9f4cbf2ef0>> could not be transformed and will be executed as-is. Please report this to the AutgoGraph team. When filing the bug, set the verbosity to 10 (on Linux, `export AUTOGRAPH_VERBOSITY=10`) and attach the full output. Cause: converting <bound method Dense.call of <tensorflow.python.layers.core.Dense object at 0x7f9f4cbf2ef0>>: AssertionError: Bad argument number for Name: 3, expecting 4
WARNING:tensorflow:Entity <bound method Dense.call of <tensorflow.python.layers.core.Dense object at 0x7f9f4cbf2ef0>> could not be transformed and will be executed as-is. Please report this to the AutgoGraph team. When filing the bug, set the verbosity to 10 (on Linux, `export AUTOGRAPH_VERBOSITY=10`) and attach the full output. Cause: converting <bound method Dense.call of <tensorflow.python.layers.core.Dense object at 0x7f9f4cbf2ef0>>: AssertionError: Bad argument number for Name: 3, expecting 4
W0609 10:07:51.469447 140324213704512 ag_logging.py:145] Entity <bound method Dense.call of <tensorflow.python.layers.core.Dense object at 0x7f9f4cbf2ef0>> could not be transformed and will be executed as-is. Please report this to the AutgoGraph team. When filing the bug, set the verbosity to 10 (on Linux, `export AUTOGRAPH_VERBOSITY=10`) and attach the full output. Cause: converting <bound method Dense.call of <tensorflow.python.layers.core.Dense object at 0x7f9f4cbf2ef0>>: AssertionError: Bad argument number for Name: 3, expecting 4
WARNING:tensorflow:Entity <bound method Dense.call of <tensorflow.python.layers.core.Dense object at 0x7f9f4cbf2ef0>> could not be transformed and will be executed as-is. Please report this to the AutgoGraph team. When filing the bug, set the verbosity to 10 (on Linux, `export AUTOGRAPH_VERBOSITY=10`) and attach the full output. Cause: converting <bound method Dense.call of <tensorflow.python.layers.core.Dense object at 0x7f9f4cbf2ef0>>: AssertionError: Bad argument number for Name: 3, expecting 4
W0609 10:07:51.568865 140324213704512 ag_logging.py:145] Entity <bound method Dense.call of <tensorflow.python.layers.core.Dense object at 0x7f9f4cbf2ef0>> could not be transformed and will be executed as-is. Please report this to the AutgoGraph team. When filing the bug, set the verbosity to 10 (on Linux, `export AUTOGRAPH_VERBOSITY=10`) and attach the full output. Cause: converting <bound method Dense.call of <tensorflow.python.layers.core.Dense object at 0x7f9f4cbf2ef0>>: AssertionError: Bad argument number for Name: 3, expecting 4
WARNING:tensorflow:From /Midgard/home/ppoklukar/anaconda3/lib/python3.7/site-packages/tensorflow_hub/saved_model_lib.py:110: build_tensor_info (from tensorflow.python.saved_model.utils_impl) is deprecated and will be removed in a future version.
Instructions for updating:
This function will only be available through the v1 compatibility library as tf.compat.v1.saved_model.utils.build_tensor_info or tf.compat.v1.saved_model.build_tensor_info.
W0609 10:07:51.572424 140324213704512 deprecation.py:323] From /Midgard/home/ppoklukar/anaconda3/lib/python3.7/site-packages/tensorflow_hub/saved_model_lib.py:110: build_tensor_info (from tensorflow.python.saved_model.utils_impl) is deprecated and will be removed in a future version.
Instructions for updating:
This function will only be available through the v1 compatibility library as tf.compat.v1.saved_model.utils.build_tensor_info or tf.compat.v1.saved_model.build_tensor_info.
WARNING:tensorflow:Entity <bound method Dense.call of <tensorflow.python.layers.core.Dense object at 0x7f9f4c113128>> could not be transformed and will be executed as-is. Please report this to the AutgoGraph team. When filing the bug, set the verbosity to 10 (on Linux, `export AUTOGRAPH_VERBOSITY=10`) and attach the full output. Cause: converting <bound method Dense.call of <tensorflow.python.layers.core.Dense object at 0x7f9f4c113128>>: AssertionError: Bad argument number for Name: 3, expecting 4
W0609 10:07:51.699627 140324213704512 ag_logging.py:145] Entity <bound method Dense.call of <tensorflow.python.layers.core.Dense object at 0x7f9f4c113128>> could not be transformed and will be executed as-is. Please report this to the AutgoGraph team. When filing the bug, set the verbosity to 10 (on Linux, `export AUTOGRAPH_VERBOSITY=10`) and attach the full output. Cause: converting <bound method Dense.call of <tensorflow.python.layers.core.Dense object at 0x7f9f4c113128>>: AssertionError: Bad argument number for Name: 3, expecting 4
WARNING:tensorflow:Entity <bound method Dense.call of <tensorflow.python.layers.core.Dense object at 0x7f9f4c113128>> could not be transformed and will be executed as-is. Please report this to the AutgoGraph team. When filing the bug, set the verbosity to 10 (on Linux, `export AUTOGRAPH_VERBOSITY=10`) and attach the full output. Cause: converting <bound method Dense.call of <tensorflow.python.layers.core.Dense object at 0x7f9f4c113128>>: AssertionError: Bad argument number for Name: 3, expecting 4
W0609 10:07:51.803725 140324213704512 ag_logging.py:145] Entity <bound method Dense.call of <tensorflow.python.layers.core.Dense object at 0x7f9f4c113128>> could not be transformed and will be executed as-is. Please report this to the AutgoGraph team. When filing the bug, set the verbosity to 10 (on Linux, `export AUTOGRAPH_VERBOSITY=10`) and attach the full output. Cause: converting <bound method Dense.call of <tensorflow.python.layers.core.Dense object at 0x7f9f4c113128>>: AssertionError: Bad argument number for Name: 3, expecting 4
WARNING:tensorflow:Entity <bound method Conv2DTranspose.call of <tensorflow.python.layers.convolutional.Conv2DTranspose object at 0x7f9f4c113128>> could not be transformed and will be executed as-is. Please report this to the AutgoGraph team. When filing the bug, set the verbosity to 10 (on Linux, `export AUTOGRAPH_VERBOSITY=10`) and attach the full output. Cause: converting <bound method Conv2DTranspose.call of <tensorflow.python.layers.convolutional.Conv2DTranspose object at 0x7f9f4c113128>>: AttributeError: module 'gast' has no attribute 'Num'
W0609 10:07:51.842170 140324213704512 ag_logging.py:145] Entity <bound method Conv2DTranspose.call of <tensorflow.python.layers.convolutional.Conv2DTranspose object at 0x7f9f4c113128>> could not be transformed and will be executed as-is. Please report this to the AutgoGraph team. When filing the bug, set the verbosity to 10 (on Linux, `export AUTOGRAPH_VERBOSITY=10`) and attach the full output. Cause: converting <bound method Conv2DTranspose.call of <tensorflow.python.layers.convolutional.Conv2DTranspose object at 0x7f9f4c113128>>: AttributeError: module 'gast' has no attribute 'Num'
WARNING:tensorflow:Entity <bound method Conv2DTranspose.call of <tensorflow.python.layers.convolutional.Conv2DTranspose object at 0x7f9f4c113128>> could not be transformed and will be executed as-is. Please report this to the AutgoGraph team. When filing the bug, set the verbosity to 10 (on Linux, `export AUTOGRAPH_VERBOSITY=10`) and attach the full output. Cause: converting <bound method Conv2DTranspose.call of <tensorflow.python.layers.convolutional.Conv2DTranspose object at 0x7f9f4c113128>>: AttributeError: module 'gast' has no attribute 'Num'
W0609 10:07:51.893470 140324213704512 ag_logging.py:145] Entity <bound method Conv2DTranspose.call of <tensorflow.python.layers.convolutional.Conv2DTranspose object at 0x7f9f4c113128>> could not be transformed and will be executed as-is. Please report this to the AutgoGraph team. When filing the bug, set the verbosity to 10 (on Linux, `export AUTOGRAPH_VERBOSITY=10`) and attach the full output. Cause: converting <bound method Conv2DTranspose.call of <tensorflow.python.layers.convolutional.Conv2DTranspose object at 0x7f9f4c113128>>: AttributeError: module 'gast' has no attribute 'Num'
WARNING:tensorflow:Entity <bound method Conv2DTranspose.call of <tensorflow.python.layers.convolutional.Conv2DTranspose object at 0x7f9f4c113128>> could not be transformed and will be executed as-is. Please report this to the AutgoGraph team. When filing the bug, set the verbosity to 10 (on Linux, `export AUTOGRAPH_VERBOSITY=10`) and attach the full output. Cause: converting <bound method Conv2DTranspose.call of <tensorflow.python.layers.convolutional.Conv2DTranspose object at 0x7f9f4c113128>>: AttributeError: module 'gast' has no attribute 'Num'
W0609 10:07:51.944815 140324213704512 ag_logging.py:145] Entity <bound method Conv2DTranspose.call of <tensorflow.python.layers.convolutional.Conv2DTranspose object at 0x7f9f4c113128>> could not be transformed and will be executed as-is. Please report this to the AutgoGraph team. When filing the bug, set the verbosity to 10 (on Linux, `export AUTOGRAPH_VERBOSITY=10`) and attach the full output. Cause: converting <bound method Conv2DTranspose.call of <tensorflow.python.layers.convolutional.Conv2DTranspose object at 0x7f9f4c113128>>: AttributeError: module 'gast' has no attribute 'Num'
WARNING:tensorflow:Entity <bound method Conv2DTranspose.call of <tensorflow.python.layers.convolutional.Conv2DTranspose object at 0x7f9f4c113128>> could not be transformed and will be executed as-is. Please report this to the AutgoGraph team. When filing the bug, set the verbosity to 10 (on Linux, `export AUTOGRAPH_VERBOSITY=10`) and attach the full output. Cause: converting <bound method Conv2DTranspose.call of <tensorflow.python.layers.convolutional.Conv2DTranspose object at 0x7f9f4c113128>>: AttributeError: module 'gast' has no attribute 'Num'
W0609 10:07:51.995328 140324213704512 ag_logging.py:145] Entity <bound method Conv2DTranspose.call of <tensorflow.python.layers.convolutional.Conv2DTranspose object at 0x7f9f4c113128>> could not be transformed and will be executed as-is. Please report this to the AutgoGraph team. When filing the bug, set the verbosity to 10 (on Linux, `export AUTOGRAPH_VERBOSITY=10`) and attach the full output. Cause: converting <bound method Conv2DTranspose.call of <tensorflow.python.layers.convolutional.Conv2DTranspose object at 0x7f9f4c113128>>: AttributeError: module 'gast' has no attribute 'Num'
WARNING:tensorflow:Entity <bound method Dense.call of <tensorflow.python.layers.core.Dense object at 0x7f9f45e90518>> could not be transformed and will be executed as-is. Please report this to the AutgoGraph team. When filing the bug, set the verbosity to 10 (on Linux, `export AUTOGRAPH_VERBOSITY=10`) and attach the full output. Cause: converting <bound method Dense.call of <tensorflow.python.layers.core.Dense object at 0x7f9f45e90518>>: AssertionError: Bad argument number for Name: 3, expecting 4
W0609 10:07:52.100361 140324213704512 ag_logging.py:145] Entity <bound method Dense.call of <tensorflow.python.layers.core.Dense object at 0x7f9f45e90518>> could not be transformed and will be executed as-is. Please report this to the AutgoGraph team. When filing the bug, set the verbosity to 10 (on Linux, `export AUTOGRAPH_VERBOSITY=10`) and attach the full output. Cause: converting <bound method Dense.call of <tensorflow.python.layers.core.Dense object at 0x7f9f45e90518>>: AssertionError: Bad argument number for Name: 3, expecting 4
WARNING:tensorflow:Entity <bound method Dense.call of <tensorflow.python.layers.core.Dense object at 0x7f9f45e90518>> could not be transformed and will be executed as-is. Please report this to the AutgoGraph team. When filing the bug, set the verbosity to 10 (on Linux, `export AUTOGRAPH_VERBOSITY=10`) and attach the full output. Cause: converting <bound method Dense.call of <tensorflow.python.layers.core.Dense object at 0x7f9f45e90518>>: AssertionError: Bad argument number for Name: 3, expecting 4
W0609 10:07:52.189427 140324213704512 ag_logging.py:145] Entity <bound method Dense.call of <tensorflow.python.layers.core.Dense object at 0x7f9f45e90518>> could not be transformed and will be executed as-is. Please report this to the AutgoGraph team. When filing the bug, set the verbosity to 10 (on Linux, `export AUTOGRAPH_VERBOSITY=10`) and attach the full output. Cause: converting <bound method Dense.call of <tensorflow.python.layers.core.Dense object at 0x7f9f45e90518>>: AssertionError: Bad argument number for Name: 3, expecting 4
WARNING:tensorflow:Entity <bound method Conv2DTranspose.call of <tensorflow.python.layers.convolutional.Conv2DTranspose object at 0x7f9f45e90550>> could not be transformed and will be executed as-is. Please report this to the AutgoGraph team. When filing the bug, set the verbosity to 10 (on Linux, `export AUTOGRAPH_VERBOSITY=10`) and attach the full output. Cause: converting <bound method Conv2DTranspose.call of <tensorflow.python.layers.convolutional.Conv2DTranspose object at 0x7f9f45e90550>>: AttributeError: module 'gast' has no attribute 'Num'
W0609 10:07:52.214194 140324213704512 ag_logging.py:145] Entity <bound method Conv2DTranspose.call of <tensorflow.python.layers.convolutional.Conv2DTranspose object at 0x7f9f45e90550>> could not be transformed and will be executed as-is. Please report this to the AutgoGraph team. When filing the bug, set the verbosity to 10 (on Linux, `export AUTOGRAPH_VERBOSITY=10`) and attach the full output. Cause: converting <bound method Conv2DTranspose.call of <tensorflow.python.layers.convolutional.Conv2DTranspose object at 0x7f9f45e90550>>: AttributeError: module 'gast' has no attribute 'Num'
WARNING:tensorflow:Entity <bound method Conv2DTranspose.call of <tensorflow.python.layers.convolutional.Conv2DTranspose object at 0x7f9f45e90550>> could not be transformed and will be executed as-is. Please report this to the AutgoGraph team. When filing the bug, set the verbosity to 10 (on Linux, `export AUTOGRAPH_VERBOSITY=10`) and attach the full output. Cause: converting <bound method Conv2DTranspose.call of <tensorflow.python.layers.convolutional.Conv2DTranspose object at 0x7f9f45e90550>>: AttributeError: module 'gast' has no attribute 'Num'
W0609 10:07:52.252227 140324213704512 ag_logging.py:145] Entity <bound method Conv2DTranspose.call of <tensorflow.python.layers.convolutional.Conv2DTranspose object at 0x7f9f45e90550>> could not be transformed and will be executed as-is. Please report this to the AutgoGraph team. When filing the bug, set the verbosity to 10 (on Linux, `export AUTOGRAPH_VERBOSITY=10`) and attach the full output. Cause: converting <bound method Conv2DTranspose.call of <tensorflow.python.layers.convolutional.Conv2DTranspose object at 0x7f9f45e90550>>: AttributeError: module 'gast' has no attribute 'Num'
WARNING:tensorflow:Entity <bound method Conv2DTranspose.call of <tensorflow.python.layers.convolutional.Conv2DTranspose object at 0x7f9f45e90550>> could not be transformed and will be executed as-is. Please report this to the AutgoGraph team. When filing the bug, set the verbosity to 10 (on Linux, `export AUTOGRAPH_VERBOSITY=10`) and attach the full output. Cause: converting <bound method Conv2DTranspose.call of <tensorflow.python.layers.convolutional.Conv2DTranspose object at 0x7f9f45e90550>>: AttributeError: module 'gast' has no attribute 'Num'
W0609 10:07:52.290031 140324213704512 ag_logging.py:145] Entity <bound method Conv2DTranspose.call of <tensorflow.python.layers.convolutional.Conv2DTranspose object at 0x7f9f45e90550>> could not be transformed and will be executed as-is. Please report this to the AutgoGraph team. When filing the bug, set the verbosity to 10 (on Linux, `export AUTOGRAPH_VERBOSITY=10`) and attach the full output. Cause: converting <bound method Conv2DTranspose.call of <tensorflow.python.layers.convolutional.Conv2DTranspose object at 0x7f9f45e90550>>: AttributeError: module 'gast' has no attribute 'Num'
WARNING:tensorflow:Entity <bound method Conv2DTranspose.call of <tensorflow.python.layers.convolutional.Conv2DTranspose object at 0x7f9f45e90550>> could not be transformed and will be executed as-is. Please report this to the AutgoGraph team. When filing the bug, set the verbosity to 10 (on Linux, `export AUTOGRAPH_VERBOSITY=10`) and attach the full output. Cause: converting <bound method Conv2DTranspose.call of <tensorflow.python.layers.convolutional.Conv2DTranspose object at 0x7f9f45e90550>>: AttributeError: module 'gast' has no attribute 'Num'
W0609 10:07:52.327380 140324213704512 ag_logging.py:145] Entity <bound method Conv2DTranspose.call of <tensorflow.python.layers.convolutional.Conv2DTranspose object at 0x7f9f45e90550>> could not be transformed and will be executed as-is. Please report this to the AutgoGraph team. When filing the bug, set the verbosity to 10 (on Linux, `export AUTOGRAPH_VERBOSITY=10`) and attach the full output. Cause: converting <bound method Conv2DTranspose.call of <tensorflow.python.layers.convolutional.Conv2DTranspose object at 0x7f9f45e90550>>: AttributeError: module 'gast' has no attribute 'Num'
WARNING:tensorflow:Entity <bound method Conv.call of <tensorflow.python.layers.convolutional.Conv2D object at 0x7f9f45c462b0>> could not be transformed and will be executed as-is. Please report this to the AutgoGraph team. When filing the bug, set the verbosity to 10 (on Linux, `export AUTOGRAPH_VERBOSITY=10`) and attach the full output. Cause: converting <bound method Conv.call of <tensorflow.python.layers.convolutional.Conv2D object at 0x7f9f45c462b0>>: AssertionError: Bad argument number for Name: 3, expecting 4
W0609 10:07:52.481886 140324213704512 ag_logging.py:145] Entity <bound method Conv.call of <tensorflow.python.layers.convolutional.Conv2D object at 0x7f9f45c462b0>> could not be transformed and will be executed as-is. Please report this to the AutgoGraph team. When filing the bug, set the verbosity to 10 (on Linux, `export AUTOGRAPH_VERBOSITY=10`) and attach the full output. Cause: converting <bound method Conv.call of <tensorflow.python.layers.convolutional.Conv2D object at 0x7f9f45c462b0>>: AssertionError: Bad argument number for Name: 3, expecting 4
WARNING:tensorflow:Entity <bound method Conv.call of <tensorflow.python.layers.convolutional.Conv2D object at 0x7f9f45e90c88>> could not be transformed and will be executed as-is. Please report this to the AutgoGraph team. When filing the bug, set the verbosity to 10 (on Linux, `export AUTOGRAPH_VERBOSITY=10`) and attach the full output. Cause: converting <bound method Conv.call of <tensorflow.python.layers.convolutional.Conv2D object at 0x7f9f45e90c88>>: AssertionError: Bad argument number for Name: 3, expecting 4
W0609 10:07:52.565427 140324213704512 ag_logging.py:145] Entity <bound method Conv.call of <tensorflow.python.layers.convolutional.Conv2D object at 0x7f9f45e90c88>> could not be transformed and will be executed as-is. Please report this to the AutgoGraph team. When filing the bug, set the verbosity to 10 (on Linux, `export AUTOGRAPH_VERBOSITY=10`) and attach the full output. Cause: converting <bound method Conv.call of <tensorflow.python.layers.convolutional.Conv2D object at 0x7f9f45e90c88>>: AssertionError: Bad argument number for Name: 3, expecting 4
WARNING:tensorflow:Entity <bound method Conv.call of <tensorflow.python.layers.convolutional.Conv2D object at 0x7f9f45e90c88>> could not be transformed and will be executed as-is. Please report this to the AutgoGraph team. When filing the bug, set the verbosity to 10 (on Linux, `export AUTOGRAPH_VERBOSITY=10`) and attach the full output. Cause: converting <bound method Conv.call of <tensorflow.python.layers.convolutional.Conv2D object at 0x7f9f45e90c88>>: AssertionError: Bad argument number for Name: 3, expecting 4
W0609 10:07:52.675320 140324213704512 ag_logging.py:145] Entity <bound method Conv.call of <tensorflow.python.layers.convolutional.Conv2D object at 0x7f9f45e90c88>> could not be transformed and will be executed as-is. Please report this to the AutgoGraph team. When filing the bug, set the verbosity to 10 (on Linux, `export AUTOGRAPH_VERBOSITY=10`) and attach the full output. Cause: converting <bound method Conv.call of <tensorflow.python.layers.convolutional.Conv2D object at 0x7f9f45e90c88>>: AssertionError: Bad argument number for Name: 3, expecting 4
WARNING:tensorflow:Entity <bound method Conv.call of <tensorflow.python.layers.convolutional.Conv2D object at 0x7f9f45e90c88>> could not be transformed and will be executed as-is. Please report this to the AutgoGraph team. When filing the bug, set the verbosity to 10 (on Linux, `export AUTOGRAPH_VERBOSITY=10`) and attach the full output. Cause: converting <bound method Conv.call of <tensorflow.python.layers.convolutional.Conv2D object at 0x7f9f45e90c88>>: AssertionError: Bad argument number for Name: 3, expecting 4
W0609 10:07:52.755539 140324213704512 ag_logging.py:145] Entity <bound method Conv.call of <tensorflow.python.layers.convolutional.Conv2D object at 0x7f9f45e90c88>> could not be transformed and will be executed as-is. Please report this to the AutgoGraph team. When filing the bug, set the verbosity to 10 (on Linux, `export AUTOGRAPH_VERBOSITY=10`) and attach the full output. Cause: converting <bound method Conv.call of <tensorflow.python.layers.convolutional.Conv2D object at 0x7f9f45e90c88>>: AssertionError: Bad argument number for Name: 3, expecting 4
WARNING:tensorflow:Entity <bound method Flatten.call of <tensorflow.python.layers.core.Flatten object at 0x7f9f45e90c88>> could not be transformed and will be executed as-is. Please report this to the AutgoGraph team. When filing the bug, set the verbosity to 10 (on Linux, `export AUTOGRAPH_VERBOSITY=10`) and attach the full output. Cause: converting <bound method Flatten.call of <tensorflow.python.layers.core.Flatten object at 0x7f9f45e90c88>>: AttributeError: module 'gast' has no attribute 'Num'
W0609 10:07:52.772218 140324213704512 ag_logging.py:145] Entity <bound method Flatten.call of <tensorflow.python.layers.core.Flatten object at 0x7f9f45e90c88>> could not be transformed and will be executed as-is. Please report this to the AutgoGraph team. When filing the bug, set the verbosity to 10 (on Linux, `export AUTOGRAPH_VERBOSITY=10`) and attach the full output. Cause: converting <bound method Flatten.call of <tensorflow.python.layers.core.Flatten object at 0x7f9f45e90c88>>: AttributeError: module 'gast' has no attribute 'Num'
WARNING:tensorflow:Entity <bound method Dense.call of <tensorflow.python.layers.core.Dense object at 0x7f9f4c113240>> could not be transformed and will be executed as-is. Please report this to the AutgoGraph team. When filing the bug, set the verbosity to 10 (on Linux, `export AUTOGRAPH_VERBOSITY=10`) and attach the full output. Cause: converting <bound method Dense.call of <tensorflow.python.layers.core.Dense object at 0x7f9f4c113240>>: AssertionError: Bad argument number for Name: 3, expecting 4
W0609 10:07:52.878651 140324213704512 ag_logging.py:145] Entity <bound method Dense.call of <tensorflow.python.layers.core.Dense object at 0x7f9f4c113240>> could not be transformed and will be executed as-is. Please report this to the AutgoGraph team. When filing the bug, set the verbosity to 10 (on Linux, `export AUTOGRAPH_VERBOSITY=10`) and attach the full output. Cause: converting <bound method Dense.call of <tensorflow.python.layers.core.Dense object at 0x7f9f4c113240>>: AssertionError: Bad argument number for Name: 3, expecting 4
WARNING:tensorflow:Entity <bound method Dense.call of <tensorflow.python.layers.core.Dense object at 0x7f9f4c113240>> could not be transformed and will be executed as-is. Please report this to the AutgoGraph team. When filing the bug, set the verbosity to 10 (on Linux, `export AUTOGRAPH_VERBOSITY=10`) and attach the full output. Cause: converting <bound method Dense.call of <tensorflow.python.layers.core.Dense object at 0x7f9f4c113240>>: AssertionError: Bad argument number for Name: 3, expecting 4
W0609 10:07:52.981806 140324213704512 ag_logging.py:145] Entity <bound method Dense.call of <tensorflow.python.layers.core.Dense object at 0x7f9f4c113240>> could not be transformed and will be executed as-is. Please report this to the AutgoGraph team. When filing the bug, set the verbosity to 10 (on Linux, `export AUTOGRAPH_VERBOSITY=10`) and attach the full output. Cause: converting <bound method Dense.call of <tensorflow.python.layers.core.Dense object at 0x7f9f4c113240>>: AssertionError: Bad argument number for Name: 3, expecting 4
WARNING:tensorflow:Entity <bound method Dense.call of <tensorflow.python.layers.core.Dense object at 0x7f9f4c113240>> could not be transformed and will be executed as-is. Please report this to the AutgoGraph team. When filing the bug, set the verbosity to 10 (on Linux, `export AUTOGRAPH_VERBOSITY=10`) and attach the full output. Cause: converting <bound method Dense.call of <tensorflow.python.layers.core.Dense object at 0x7f9f4c113240>>: AssertionError: Bad argument number for Name: 3, expecting 4
W0609 10:07:53.084481 140324213704512 ag_logging.py:145] Entity <bound method Dense.call of <tensorflow.python.layers.core.Dense object at 0x7f9f4c113240>> could not be transformed and will be executed as-is. Please report this to the AutgoGraph team. When filing the bug, set the verbosity to 10 (on Linux, `export AUTOGRAPH_VERBOSITY=10`) and attach the full output. Cause: converting <bound method Dense.call of <tensorflow.python.layers.core.Dense object at 0x7f9f4c113240>>: AssertionError: Bad argument number for Name: 3, expecting 4
WARNING:tensorflow:Entity <bound method Dense.call of <tensorflow.python.layers.core.Dense object at 0x7f9f4c113240>> could not be transformed and will be executed as-is. Please report this to the AutgoGraph team. When filing the bug, set the verbosity to 10 (on Linux, `export AUTOGRAPH_VERBOSITY=10`) and attach the full output. Cause: converting <bound method Dense.call of <tensorflow.python.layers.core.Dense object at 0x7f9f4c113240>>: AssertionError: Bad argument number for Name: 3, expecting 4
W0609 10:07:53.203391 140324213704512 ag_logging.py:145] Entity <bound method Dense.call of <tensorflow.python.layers.core.Dense object at 0x7f9f4c113240>> could not be transformed and will be executed as-is. Please report this to the AutgoGraph team. When filing the bug, set the verbosity to 10 (on Linux, `export AUTOGRAPH_VERBOSITY=10`) and attach the full output. Cause: converting <bound method Dense.call of <tensorflow.python.layers.core.Dense object at 0x7f9f4c113240>>: AssertionError: Bad argument number for Name: 3, expecting 4
WARNING:tensorflow:Entity <bound method Dense.call of <tensorflow.python.layers.core.Dense object at 0x7f9f4c113240>> could not be transformed and will be executed as-is. Please report this to the AutgoGraph team. When filing the bug, set the verbosity to 10 (on Linux, `export AUTOGRAPH_VERBOSITY=10`) and attach the full output. Cause: converting <bound method Dense.call of <tensorflow.python.layers.core.Dense object at 0x7f9f4c113240>>: AssertionError: Bad argument number for Name: 3, expecting 4
W0609 10:07:53.301875 140324213704512 ag_logging.py:145] Entity <bound method Dense.call of <tensorflow.python.layers.core.Dense object at 0x7f9f4c113240>> could not be transformed and will be executed as-is. Please report this to the AutgoGraph team. When filing the bug, set the verbosity to 10 (on Linux, `export AUTOGRAPH_VERBOSITY=10`) and attach the full output. Cause: converting <bound method Dense.call of <tensorflow.python.layers.core.Dense object at 0x7f9f4c113240>>: AssertionError: Bad argument number for Name: 3, expecting 4
WARNING:tensorflow:Entity <bound method Conv2DTranspose.call of <tensorflow.python.layers.convolutional.Conv2DTranspose object at 0x7f9f45b58b70>> could not be transformed and will be executed as-is. Please report this to the AutgoGraph team. When filing the bug, set the verbosity to 10 (on Linux, `export AUTOGRAPH_VERBOSITY=10`) and attach the full output. Cause: converting <bound method Conv2DTranspose.call of <tensorflow.python.layers.convolutional.Conv2DTranspose object at 0x7f9f45b58b70>>: AttributeError: module 'gast' has no attribute 'Num'
W0609 10:07:53.338213 140324213704512 ag_logging.py:145] Entity <bound method Conv2DTranspose.call of <tensorflow.python.layers.convolutional.Conv2DTranspose object at 0x7f9f45b58b70>> could not be transformed and will be executed as-is. Please report this to the AutgoGraph team. When filing the bug, set the verbosity to 10 (on Linux, `export AUTOGRAPH_VERBOSITY=10`) and attach the full output. Cause: converting <bound method Conv2DTranspose.call of <tensorflow.python.layers.convolutional.Conv2DTranspose object at 0x7f9f45b58b70>>: AttributeError: module 'gast' has no attribute 'Num'
WARNING:tensorflow:Entity <bound method Conv2DTranspose.call of <tensorflow.python.layers.convolutional.Conv2DTranspose object at 0x7f9f45b58b70>> could not be transformed and will be executed as-is. Please report this to the AutgoGraph team. When filing the bug, set the verbosity to 10 (on Linux, `export AUTOGRAPH_VERBOSITY=10`) and attach the full output. Cause: converting <bound method Conv2DTranspose.call of <tensorflow.python.layers.convolutional.Conv2DTranspose object at 0x7f9f45b58b70>>: AttributeError: module 'gast' has no attribute 'Num'
W0609 10:07:53.386805 140324213704512 ag_logging.py:145] Entity <bound method Conv2DTranspose.call of <tensorflow.python.layers.convolutional.Conv2DTranspose object at 0x7f9f45b58b70>> could not be transformed and will be executed as-is. Please report this to the AutgoGraph team. When filing the bug, set the verbosity to 10 (on Linux, `export AUTOGRAPH_VERBOSITY=10`) and attach the full output. Cause: converting <bound method Conv2DTranspose.call of <tensorflow.python.layers.convolutional.Conv2DTranspose object at 0x7f9f45b58b70>>: AttributeError: module 'gast' has no attribute 'Num'
WARNING:tensorflow:Entity <bound method Conv2DTranspose.call of <tensorflow.python.layers.convolutional.Conv2DTranspose object at 0x7f9f45b58b70>> could not be transformed and will be executed as-is. Please report this to the AutgoGraph team. When filing the bug, set the verbosity to 10 (on Linux, `export AUTOGRAPH_VERBOSITY=10`) and attach the full output. Cause: converting <bound method Conv2DTranspose.call of <tensorflow.python.layers.convolutional.Conv2DTranspose object at 0x7f9f45b58b70>>: AttributeError: module 'gast' has no attribute 'Num'
W0609 10:07:53.435659 140324213704512 ag_logging.py:145] Entity <bound method Conv2DTranspose.call of <tensorflow.python.layers.convolutional.Conv2DTranspose object at 0x7f9f45b58b70>> could not be transformed and will be executed as-is. Please report this to the AutgoGraph team. When filing the bug, set the verbosity to 10 (on Linux, `export AUTOGRAPH_VERBOSITY=10`) and attach the full output. Cause: converting <bound method Conv2DTranspose.call of <tensorflow.python.layers.convolutional.Conv2DTranspose object at 0x7f9f45b58b70>>: AttributeError: module 'gast' has no attribute 'Num'
WARNING:tensorflow:Entity <bound method Conv2DTranspose.call of <tensorflow.python.layers.convolutional.Conv2DTranspose object at 0x7f9f45b58b70>> could not be transformed and will be executed as-is. Please report this to the AutgoGraph team. When filing the bug, set the verbosity to 10 (on Linux, `export AUTOGRAPH_VERBOSITY=10`) and attach the full output. Cause: converting <bound method Conv2DTranspose.call of <tensorflow.python.layers.convolutional.Conv2DTranspose object at 0x7f9f45b58b70>>: AttributeError: module 'gast' has no attribute 'Num'
W0609 10:07:53.484129 140324213704512 ag_logging.py:145] Entity <bound method Conv2DTranspose.call of <tensorflow.python.layers.convolutional.Conv2DTranspose object at 0x7f9f45b58b70>> could not be transformed and will be executed as-is. Please report this to the AutgoGraph team. When filing the bug, set the verbosity to 10 (on Linux, `export AUTOGRAPH_VERBOSITY=10`) and attach the full output. Cause: converting <bound method Conv2DTranspose.call of <tensorflow.python.layers.convolutional.Conv2DTranspose object at 0x7f9f45b58b70>>: AttributeError: module 'gast' has no attribute 'Num'
WARNING:tensorflow:Entity <bound method Dense.call of <tensorflow.python.layers.core.Dense object at 0x7f9f45b58b70>> could not be transformed and will be executed as-is. Please report this to the AutgoGraph team. When filing the bug, set the verbosity to 10 (on Linux, `export AUTOGRAPH_VERBOSITY=10`) and attach the full output. Cause: converting <bound method Dense.call of <tensorflow.python.layers.core.Dense object at 0x7f9f45b58b70>>: AssertionError: Bad argument number for Name: 3, expecting 4
W0609 10:07:53.588643 140324213704512 ag_logging.py:145] Entity <bound method Dense.call of <tensorflow.python.layers.core.Dense object at 0x7f9f45b58b70>> could not be transformed and will be executed as-is. Please report this to the AutgoGraph team. When filing the bug, set the verbosity to 10 (on Linux, `export AUTOGRAPH_VERBOSITY=10`) and attach the full output. Cause: converting <bound method Dense.call of <tensorflow.python.layers.core.Dense object at 0x7f9f45b58b70>>: AssertionError: Bad argument number for Name: 3, expecting 4
WARNING:tensorflow:Entity <bound method Dense.call of <tensorflow.python.layers.core.Dense object at 0x7f9f45b58b70>> could not be transformed and will be executed as-is. Please report this to the AutgoGraph team. When filing the bug, set the verbosity to 10 (on Linux, `export AUTOGRAPH_VERBOSITY=10`) and attach the full output. Cause: converting <bound method Dense.call of <tensorflow.python.layers.core.Dense object at 0x7f9f45b58b70>>: AssertionError: Bad argument number for Name: 3, expecting 4
W0609 10:07:53.829836 140324213704512 ag_logging.py:145] Entity <bound method Dense.call of <tensorflow.python.layers.core.Dense object at 0x7f9f45b58b70>> could not be transformed and will be executed as-is. Please report this to the AutgoGraph team. When filing the bug, set the verbosity to 10 (on Linux, `export AUTOGRAPH_VERBOSITY=10`) and attach the full output. Cause: converting <bound method Dense.call of <tensorflow.python.layers.core.Dense object at 0x7f9f45b58b70>>: AssertionError: Bad argument number for Name: 3, expecting 4
WARNING:tensorflow:Entity <bound method Conv2DTranspose.call of <tensorflow.python.layers.convolutional.Conv2DTranspose object at 0x7f9f45a75198>> could not be transformed and will be executed as-is. Please report this to the AutgoGraph team. When filing the bug, set the verbosity to 10 (on Linux, `export AUTOGRAPH_VERBOSITY=10`) and attach the full output. Cause: converting <bound method Conv2DTranspose.call of <tensorflow.python.layers.convolutional.Conv2DTranspose object at 0x7f9f45a75198>>: AttributeError: module 'gast' has no attribute 'Num'
W0609 10:07:53.854146 140324213704512 ag_logging.py:145] Entity <bound method Conv2DTranspose.call of <tensorflow.python.layers.convolutional.Conv2DTranspose object at 0x7f9f45a75198>> could not be transformed and will be executed as-is. Please report this to the AutgoGraph team. When filing the bug, set the verbosity to 10 (on Linux, `export AUTOGRAPH_VERBOSITY=10`) and attach the full output. Cause: converting <bound method Conv2DTranspose.call of <tensorflow.python.layers.convolutional.Conv2DTranspose object at 0x7f9f45a75198>>: AttributeError: module 'gast' has no attribute 'Num'
WARNING:tensorflow:Entity <bound method Conv2DTranspose.call of <tensorflow.python.layers.convolutional.Conv2DTranspose object at 0x7f9f45a75198>> could not be transformed and will be executed as-is. Please report this to the AutgoGraph team. When filing the bug, set the verbosity to 10 (on Linux, `export AUTOGRAPH_VERBOSITY=10`) and attach the full output. Cause: converting <bound method Conv2DTranspose.call of <tensorflow.python.layers.convolutional.Conv2DTranspose object at 0x7f9f45a75198>>: AttributeError: module 'gast' has no attribute 'Num'
W0609 10:07:53.891580 140324213704512 ag_logging.py:145] Entity <bound method Conv2DTranspose.call of <tensorflow.python.layers.convolutional.Conv2DTranspose object at 0x7f9f45a75198>> could not be transformed and will be executed as-is. Please report this to the AutgoGraph team. When filing the bug, set the verbosity to 10 (on Linux, `export AUTOGRAPH_VERBOSITY=10`) and attach the full output. Cause: converting <bound method Conv2DTranspose.call of <tensorflow.python.layers.convolutional.Conv2DTranspose object at 0x7f9f45a75198>>: AttributeError: module 'gast' has no attribute 'Num'
WARNING:tensorflow:Entity <bound method Conv2DTranspose.call of <tensorflow.python.layers.convolutional.Conv2DTranspose object at 0x7f9f45a75198>> could not be transformed and will be executed as-is. Please report this to the AutgoGraph team. When filing the bug, set the verbosity to 10 (on Linux, `export AUTOGRAPH_VERBOSITY=10`) and attach the full output. Cause: converting <bound method Conv2DTranspose.call of <tensorflow.python.layers.convolutional.Conv2DTranspose object at 0x7f9f45a75198>>: AttributeError: module 'gast' has no attribute 'Num'
W0609 10:07:53.929215 140324213704512 ag_logging.py:145] Entity <bound method Conv2DTranspose.call of <tensorflow.python.layers.convolutional.Conv2DTranspose object at 0x7f9f45a75198>> could not be transformed and will be executed as-is. Please report this to the AutgoGraph team. When filing the bug, set the verbosity to 10 (on Linux, `export AUTOGRAPH_VERBOSITY=10`) and attach the full output. Cause: converting <bound method Conv2DTranspose.call of <tensorflow.python.layers.convolutional.Conv2DTranspose object at 0x7f9f45a75198>>: AttributeError: module 'gast' has no attribute 'Num'
WARNING:tensorflow:Entity <bound method Conv2DTranspose.call of <tensorflow.python.layers.convolutional.Conv2DTranspose object at 0x7f9f45b58b70>> could not be transformed and will be executed as-is. Please report this to the AutgoGraph team. When filing the bug, set the verbosity to 10 (on Linux, `export AUTOGRAPH_VERBOSITY=10`) and attach the full output. Cause: converting <bound method Conv2DTranspose.call of <tensorflow.python.layers.convolutional.Conv2DTranspose object at 0x7f9f45b58b70>>: AttributeError: module 'gast' has no attribute 'Num'
W0609 10:07:53.967194 140324213704512 ag_logging.py:145] Entity <bound method Conv2DTranspose.call of <tensorflow.python.layers.convolutional.Conv2DTranspose object at 0x7f9f45b58b70>> could not be transformed and will be executed as-is. Please report this to the AutgoGraph team. When filing the bug, set the verbosity to 10 (on Linux, `export AUTOGRAPH_VERBOSITY=10`) and attach the full output. Cause: converting <bound method Conv2DTranspose.call of <tensorflow.python.layers.convolutional.Conv2DTranspose object at 0x7f9f45b58b70>>: AttributeError: module 'gast' has no attribute 'Num'
2020-06-09 10:07:54.288101: I tensorflow/core/common_runtime/gpu/gpu_device.cc:1640] Found device 0 with properties: 
name: GeForce GTX 1080 Ti major: 6 minor: 1 memoryClockRate(GHz): 1.62
pciBusID: 0000:81:00.0
2020-06-09 10:07:54.288196: I tensorflow/stream_executor/platform/default/dso_loader.cc:42] Successfully opened dynamic library libcudart.so.10.0
2020-06-09 10:07:54.288218: I tensorflow/stream_executor/platform/default/dso_loader.cc:42] Successfully opened dynamic library libcublas.so.10.0
2020-06-09 10:07:54.288237: I tensorflow/stream_executor/platform/default/dso_loader.cc:42] Successfully opened dynamic library libcufft.so.10.0
2020-06-09 10:07:54.288255: I tensorflow/stream_executor/platform/default/dso_loader.cc:42] Successfully opened dynamic library libcurand.so.10.0
2020-06-09 10:07:54.288274: I tensorflow/stream_executor/platform/default/dso_loader.cc:42] Successfully opened dynamic library libcusolver.so.10.0
2020-06-09 10:07:54.288292: I tensorflow/stream_executor/platform/default/dso_loader.cc:42] Successfully opened dynamic library libcusparse.so.10.0
2020-06-09 10:07:54.288414: I tensorflow/stream_executor/platform/default/dso_loader.cc:53] Could not dlopen library 'libcudnn.so.7'; dlerror: libcudnn.so.7: cannot open shared object file: No such file or directory
2020-06-09 10:07:54.288424: W tensorflow/core/common_runtime/gpu/gpu_device.cc:1663] Cannot dlopen some GPU libraries. Skipping registering GPU devices...
2020-06-09 10:07:54.288728: I tensorflow/core/common_runtime/gpu/gpu_device.cc:1181] Device interconnect StreamExecutor with strength 1 edge matrix:
2020-06-09 10:07:54.288744: I tensorflow/core/common_runtime/gpu/gpu_device.cc:1187]      
I0609 10:07:54.537491 140324213704512 native_module.py:405] Exported TF-Hub module to: 3dshapes_models/vae3dshapes_model_s1000_1602/model/tfhub
INFO:tensorflow:Calling model_fn.
I0609 10:07:54.586970 140324213704512 estimator.py:1145] Calling model_fn.
INFO:tensorflow:Running eval on CPU
I0609 10:07:54.587202 140324213704512 tpu_estimator.py:2965] Running eval on CPU
WARNING:tensorflow:Entity <bound method Conv.call of <tensorflow.python.layers.convolutional.Conv2D object at 0x7f9f4d1ecba8>> could not be transformed and will be executed as-is. Please report this to the AutgoGraph team. When filing the bug, set the verbosity to 10 (on Linux, `export AUTOGRAPH_VERBOSITY=10`) and attach the full output. Cause: converting <bound method Conv.call of <tensorflow.python.layers.convolutional.Conv2D object at 0x7f9f4d1ecba8>>: AssertionError: Bad argument number for Name: 3, expecting 4
W0609 10:07:54.659017 140324213704512 ag_logging.py:145] Entity <bound method Conv.call of <tensorflow.python.layers.convolutional.Conv2D object at 0x7f9f4d1ecba8>> could not be transformed and will be executed as-is. Please report this to the AutgoGraph team. When filing the bug, set the verbosity to 10 (on Linux, `export AUTOGRAPH_VERBOSITY=10`) and attach the full output. Cause: converting <bound method Conv.call of <tensorflow.python.layers.convolutional.Conv2D object at 0x7f9f4d1ecba8>>: AssertionError: Bad argument number for Name: 3, expecting 4
WARNING:tensorflow:Entity <bound method Conv.call of <tensorflow.python.layers.convolutional.Conv2D object at 0x7f9f4d1e0940>> could not be transformed and will be executed as-is. Please report this to the AutgoGraph team. When filing the bug, set the verbosity to 10 (on Linux, `export AUTOGRAPH_VERBOSITY=10`) and attach the full output. Cause: converting <bound method Conv.call of <tensorflow.python.layers.convolutional.Conv2D object at 0x7f9f4d1e0940>>: AssertionError: Bad argument number for Name: 3, expecting 4
W0609 10:07:54.733129 140324213704512 ag_logging.py:145] Entity <bound method Conv.call of <tensorflow.python.layers.convolutional.Conv2D object at 0x7f9f4d1e0940>> could not be transformed and will be executed as-is. Please report this to the AutgoGraph team. When filing the bug, set the verbosity to 10 (on Linux, `export AUTOGRAPH_VERBOSITY=10`) and attach the full output. Cause: converting <bound method Conv.call of <tensorflow.python.layers.convolutional.Conv2D object at 0x7f9f4d1e0940>>: AssertionError: Bad argument number for Name: 3, expecting 4
WARNING:tensorflow:Entity <bound method Conv.call of <tensorflow.python.layers.convolutional.Conv2D object at 0x7f9f4d1e0940>> could not be transformed and will be executed as-is. Please report this to the AutgoGraph team. When filing the bug, set the verbosity to 10 (on Linux, `export AUTOGRAPH_VERBOSITY=10`) and attach the full output. Cause: converting <bound method Conv.call of <tensorflow.python.layers.convolutional.Conv2D object at 0x7f9f4d1e0940>>: AssertionError: Bad argument number for Name: 3, expecting 4
W0609 10:07:54.807847 140324213704512 ag_logging.py:145] Entity <bound method Conv.call of <tensorflow.python.layers.convolutional.Conv2D object at 0x7f9f4d1e0940>> could not be transformed and will be executed as-is. Please report this to the AutgoGraph team. When filing the bug, set the verbosity to 10 (on Linux, `export AUTOGRAPH_VERBOSITY=10`) and attach the full output. Cause: converting <bound method Conv.call of <tensorflow.python.layers.convolutional.Conv2D object at 0x7f9f4d1e0940>>: AssertionError: Bad argument number for Name: 3, expecting 4
WARNING:tensorflow:Entity <bound method Conv.call of <tensorflow.python.layers.convolutional.Conv2D object at 0x7f9f4d1e0940>> could not be transformed and will be executed as-is. Please report this to the AutgoGraph team. When filing the bug, set the verbosity to 10 (on Linux, `export AUTOGRAPH_VERBOSITY=10`) and attach the full output. Cause: converting <bound method Conv.call of <tensorflow.python.layers.convolutional.Conv2D object at 0x7f9f4d1e0940>>: AssertionError: Bad argument number for Name: 3, expecting 4
W0609 10:07:54.881590 140324213704512 ag_logging.py:145] Entity <bound method Conv.call of <tensorflow.python.layers.convolutional.Conv2D object at 0x7f9f4d1e0940>> could not be transformed and will be executed as-is. Please report this to the AutgoGraph team. When filing the bug, set the verbosity to 10 (on Linux, `export AUTOGRAPH_VERBOSITY=10`) and attach the full output. Cause: converting <bound method Conv.call of <tensorflow.python.layers.convolutional.Conv2D object at 0x7f9f4d1e0940>>: AssertionError: Bad argument number for Name: 3, expecting 4
WARNING:tensorflow:Entity <bound method Flatten.call of <tensorflow.python.layers.core.Flatten object at 0x7f9f4d1e0940>> could not be transformed and will be executed as-is. Please report this to the AutgoGraph team. When filing the bug, set the verbosity to 10 (on Linux, `export AUTOGRAPH_VERBOSITY=10`) and attach the full output. Cause: converting <bound method Flatten.call of <tensorflow.python.layers.core.Flatten object at 0x7f9f4d1e0940>>: AttributeError: module 'gast' has no attribute 'Num'
W0609 10:07:54.896461 140324213704512 ag_logging.py:145] Entity <bound method Flatten.call of <tensorflow.python.layers.core.Flatten object at 0x7f9f4d1e0940>> could not be transformed and will be executed as-is. Please report this to the AutgoGraph team. When filing the bug, set the verbosity to 10 (on Linux, `export AUTOGRAPH_VERBOSITY=10`) and attach the full output. Cause: converting <bound method Flatten.call of <tensorflow.python.layers.core.Flatten object at 0x7f9f4d1e0940>>: AttributeError: module 'gast' has no attribute 'Num'
WARNING:tensorflow:Entity <bound method Dense.call of <tensorflow.python.layers.core.Dense object at 0x7f9f4d1e0940>> could not be transformed and will be executed as-is. Please report this to the AutgoGraph team. When filing the bug, set the verbosity to 10 (on Linux, `export AUTOGRAPH_VERBOSITY=10`) and attach the full output. Cause: converting <bound method Dense.call of <tensorflow.python.layers.core.Dense object at 0x7f9f4d1e0940>>: AssertionError: Bad argument number for Name: 3, expecting 4
W0609 10:07:54.992122 140324213704512 ag_logging.py:145] Entity <bound method Dense.call of <tensorflow.python.layers.core.Dense object at 0x7f9f4d1e0940>> could not be transformed and will be executed as-is. Please report this to the AutgoGraph team. When filing the bug, set the verbosity to 10 (on Linux, `export AUTOGRAPH_VERBOSITY=10`) and attach the full output. Cause: converting <bound method Dense.call of <tensorflow.python.layers.core.Dense object at 0x7f9f4d1e0940>>: AssertionError: Bad argument number for Name: 3, expecting 4
WARNING:tensorflow:Entity <bound method Dense.call of <tensorflow.python.layers.core.Dense object at 0x7f9f4d1e0940>> could not be transformed and will be executed as-is. Please report this to the AutgoGraph team. When filing the bug, set the verbosity to 10 (on Linux, `export AUTOGRAPH_VERBOSITY=10`) and attach the full output. Cause: converting <bound method Dense.call of <tensorflow.python.layers.core.Dense object at 0x7f9f4d1e0940>>: AssertionError: Bad argument number for Name: 3, expecting 4
W0609 10:07:55.092879 140324213704512 ag_logging.py:145] Entity <bound method Dense.call of <tensorflow.python.layers.core.Dense object at 0x7f9f4d1e0940>> could not be transformed and will be executed as-is. Please report this to the AutgoGraph team. When filing the bug, set the verbosity to 10 (on Linux, `export AUTOGRAPH_VERBOSITY=10`) and attach the full output. Cause: converting <bound method Dense.call of <tensorflow.python.layers.core.Dense object at 0x7f9f4d1e0940>>: AssertionError: Bad argument number for Name: 3, expecting 4
WARNING:tensorflow:Entity <bound method Dense.call of <tensorflow.python.layers.core.Dense object at 0x7f9f4d1e0940>> could not be transformed and will be executed as-is. Please report this to the AutgoGraph team. When filing the bug, set the verbosity to 10 (on Linux, `export AUTOGRAPH_VERBOSITY=10`) and attach the full output. Cause: converting <bound method Dense.call of <tensorflow.python.layers.core.Dense object at 0x7f9f4d1e0940>>: AssertionError: Bad argument number for Name: 3, expecting 4
W0609 10:07:55.188930 140324213704512 ag_logging.py:145] Entity <bound method Dense.call of <tensorflow.python.layers.core.Dense object at 0x7f9f4d1e0940>> could not be transformed and will be executed as-is. Please report this to the AutgoGraph team. When filing the bug, set the verbosity to 10 (on Linux, `export AUTOGRAPH_VERBOSITY=10`) and attach the full output. Cause: converting <bound method Dense.call of <tensorflow.python.layers.core.Dense object at 0x7f9f4d1e0940>>: AssertionError: Bad argument number for Name: 3, expecting 4
WARNING:tensorflow:Entity <bound method Dense.call of <tensorflow.python.layers.core.Dense object at 0x7f9f45cfc278>> could not be transformed and will be executed as-is. Please report this to the AutgoGraph team. When filing the bug, set the verbosity to 10 (on Linux, `export AUTOGRAPH_VERBOSITY=10`) and attach the full output. Cause: converting <bound method Dense.call of <tensorflow.python.layers.core.Dense object at 0x7f9f45cfc278>>: AssertionError: Bad argument number for Name: 3, expecting 4
W0609 10:07:55.290498 140324213704512 ag_logging.py:145] Entity <bound method Dense.call of <tensorflow.python.layers.core.Dense object at 0x7f9f45cfc278>> could not be transformed and will be executed as-is. Please report this to the AutgoGraph team. When filing the bug, set the verbosity to 10 (on Linux, `export AUTOGRAPH_VERBOSITY=10`) and attach the full output. Cause: converting <bound method Dense.call of <tensorflow.python.layers.core.Dense object at 0x7f9f45cfc278>>: AssertionError: Bad argument number for Name: 3, expecting 4
WARNING:tensorflow:Entity <bound method Dense.call of <tensorflow.python.layers.core.Dense object at 0x7f9f45cfc278>> could not be transformed and will be executed as-is. Please report this to the AutgoGraph team. When filing the bug, set the verbosity to 10 (on Linux, `export AUTOGRAPH_VERBOSITY=10`) and attach the full output. Cause: converting <bound method Dense.call of <tensorflow.python.layers.core.Dense object at 0x7f9f45cfc278>>: AssertionError: Bad argument number for Name: 3, expecting 4
W0609 10:07:55.389428 140324213704512 ag_logging.py:145] Entity <bound method Dense.call of <tensorflow.python.layers.core.Dense object at 0x7f9f45cfc278>> could not be transformed and will be executed as-is. Please report this to the AutgoGraph team. When filing the bug, set the verbosity to 10 (on Linux, `export AUTOGRAPH_VERBOSITY=10`) and attach the full output. Cause: converting <bound method Dense.call of <tensorflow.python.layers.core.Dense object at 0x7f9f45cfc278>>: AssertionError: Bad argument number for Name: 3, expecting 4
WARNING:tensorflow:Entity <bound method Conv2DTranspose.call of <tensorflow.python.layers.convolutional.Conv2DTranspose object at 0x7f9f45f16e10>> could not be transformed and will be executed as-is. Please report this to the AutgoGraph team. When filing the bug, set the verbosity to 10 (on Linux, `export AUTOGRAPH_VERBOSITY=10`) and attach the full output. Cause: converting <bound method Conv2DTranspose.call of <tensorflow.python.layers.convolutional.Conv2DTranspose object at 0x7f9f45f16e10>>: AttributeError: module 'gast' has no attribute 'Num'
W0609 10:07:55.423319 140324213704512 ag_logging.py:145] Entity <bound method Conv2DTranspose.call of <tensorflow.python.layers.convolutional.Conv2DTranspose object at 0x7f9f45f16e10>> could not be transformed and will be executed as-is. Please report this to the AutgoGraph team. When filing the bug, set the verbosity to 10 (on Linux, `export AUTOGRAPH_VERBOSITY=10`) and attach the full output. Cause: converting <bound method Conv2DTranspose.call of <tensorflow.python.layers.convolutional.Conv2DTranspose object at 0x7f9f45f16e10>>: AttributeError: module 'gast' has no attribute 'Num'
WARNING:tensorflow:Entity <bound method Conv2DTranspose.call of <tensorflow.python.layers.convolutional.Conv2DTranspose object at 0x7f9f45f16e10>> could not be transformed and will be executed as-is. Please report this to the AutgoGraph team. When filing the bug, set the verbosity to 10 (on Linux, `export AUTOGRAPH_VERBOSITY=10`) and attach the full output. Cause: converting <bound method Conv2DTranspose.call of <tensorflow.python.layers.convolutional.Conv2DTranspose object at 0x7f9f45f16e10>>: AttributeError: module 'gast' has no attribute 'Num'
W0609 10:07:55.471214 140324213704512 ag_logging.py:145] Entity <bound method Conv2DTranspose.call of <tensorflow.python.layers.convolutional.Conv2DTranspose object at 0x7f9f45f16e10>> could not be transformed and will be executed as-is. Please report this to the AutgoGraph team. When filing the bug, set the verbosity to 10 (on Linux, `export AUTOGRAPH_VERBOSITY=10`) and attach the full output. Cause: converting <bound method Conv2DTranspose.call of <tensorflow.python.layers.convolutional.Conv2DTranspose object at 0x7f9f45f16e10>>: AttributeError: module 'gast' has no attribute 'Num'
WARNING:tensorflow:Entity <bound method Conv2DTranspose.call of <tensorflow.python.layers.convolutional.Conv2DTranspose object at 0x7f9f45f16e10>> could not be transformed and will be executed as-is. Please report this to the AutgoGraph team. When filing the bug, set the verbosity to 10 (on Linux, `export AUTOGRAPH_VERBOSITY=10`) and attach the full output. Cause: converting <bound method Conv2DTranspose.call of <tensorflow.python.layers.convolutional.Conv2DTranspose object at 0x7f9f45f16e10>>: AttributeError: module 'gast' has no attribute 'Num'
W0609 10:07:55.518549 140324213704512 ag_logging.py:145] Entity <bound method Conv2DTranspose.call of <tensorflow.python.layers.convolutional.Conv2DTranspose object at 0x7f9f45f16e10>> could not be transformed and will be executed as-is. Please report this to the AutgoGraph team. When filing the bug, set the verbosity to 10 (on Linux, `export AUTOGRAPH_VERBOSITY=10`) and attach the full output. Cause: converting <bound method Conv2DTranspose.call of <tensorflow.python.layers.convolutional.Conv2DTranspose object at 0x7f9f45f16e10>>: AttributeError: module 'gast' has no attribute 'Num'
WARNING:tensorflow:Entity <bound method Conv2DTranspose.call of <tensorflow.python.layers.convolutional.Conv2DTranspose object at 0x7f9f45cfc278>> could not be transformed and will be executed as-is. Please report this to the AutgoGraph team. When filing the bug, set the verbosity to 10 (on Linux, `export AUTOGRAPH_VERBOSITY=10`) and attach the full output. Cause: converting <bound method Conv2DTranspose.call of <tensorflow.python.layers.convolutional.Conv2DTranspose object at 0x7f9f45cfc278>>: AttributeError: module 'gast' has no attribute 'Num'
W0609 10:07:55.566270 140324213704512 ag_logging.py:145] Entity <bound method Conv2DTranspose.call of <tensorflow.python.layers.convolutional.Conv2DTranspose object at 0x7f9f45cfc278>> could not be transformed and will be executed as-is. Please report this to the AutgoGraph team. When filing the bug, set the verbosity to 10 (on Linux, `export AUTOGRAPH_VERBOSITY=10`) and attach the full output. Cause: converting <bound method Conv2DTranspose.call of <tensorflow.python.layers.convolutional.Conv2DTranspose object at 0x7f9f45cfc278>>: AttributeError: module 'gast' has no attribute 'Num'
WARNING:tensorflow:From ../disentanglement_lib/methods/unsupervised/vae.py:129: The name tf.metrics.mean is deprecated. Please use tf.compat.v1.metrics.mean instead.

W0609 10:07:55.598263 140324213704512 deprecation_wrapper.py:119] From ../disentanglement_lib/methods/unsupervised/vae.py:129: The name tf.metrics.mean is deprecated. Please use tf.compat.v1.metrics.mean instead.

INFO:tensorflow:Done calling model_fn.
I0609 10:07:55.651029 140324213704512 estimator.py:1147] Done calling model_fn.
INFO:tensorflow:Starting evaluation at 2020-06-09T10:07:55Z
I0609 10:07:55.670186 140324213704512 evaluation.py:255] Starting evaluation at 2020-06-09T10:07:55Z
INFO:tensorflow:Graph was finalized.
I0609 10:07:55.907335 140324213704512 monitored_session.py:240] Graph was finalized.
2020-06-09 10:07:55.909218: I tensorflow/core/common_runtime/gpu/gpu_device.cc:1640] Found device 0 with properties: 
name: GeForce GTX 1080 Ti major: 6 minor: 1 memoryClockRate(GHz): 1.62
pciBusID: 0000:81:00.0
2020-06-09 10:07:55.909296: I tensorflow/stream_executor/platform/default/dso_loader.cc:42] Successfully opened dynamic library libcudart.so.10.0
2020-06-09 10:07:55.909322: I tensorflow/stream_executor/platform/default/dso_loader.cc:42] Successfully opened dynamic library libcublas.so.10.0
2020-06-09 10:07:55.909359: I tensorflow/stream_executor/platform/default/dso_loader.cc:42] Successfully opened dynamic library libcufft.so.10.0
2020-06-09 10:07:55.909380: I tensorflow/stream_executor/platform/default/dso_loader.cc:42] Successfully opened dynamic library libcurand.so.10.0
2020-06-09 10:07:55.909400: I tensorflow/stream_executor/platform/default/dso_loader.cc:42] Successfully opened dynamic library libcusolver.so.10.0
2020-06-09 10:07:55.909420: I tensorflow/stream_executor/platform/default/dso_loader.cc:42] Successfully opened dynamic library libcusparse.so.10.0
2020-06-09 10:07:55.909542: I tensorflow/stream_executor/platform/default/dso_loader.cc:53] Could not dlopen library 'libcudnn.so.7'; dlerror: libcudnn.so.7: cannot open shared object file: No such file or directory
2020-06-09 10:07:55.909553: W tensorflow/core/common_runtime/gpu/gpu_device.cc:1663] Cannot dlopen some GPU libraries. Skipping registering GPU devices...
2020-06-09 10:07:55.909576: I tensorflow/core/common_runtime/gpu/gpu_device.cc:1181] Device interconnect StreamExecutor with strength 1 edge matrix:
2020-06-09 10:07:55.909583: I tensorflow/core/common_runtime/gpu/gpu_device.cc:1187]      0 
2020-06-09 10:07:55.909589: I tensorflow/core/common_runtime/gpu/gpu_device.cc:1200] 0:   N 
WARNING:tensorflow:From /Midgard/home/ppoklukar/anaconda3/lib/python3.7/site-packages/tensorflow/python/training/saver.py:1276: checkpoint_exists (from tensorflow.python.training.checkpoint_management) is deprecated and will be removed in a future version.
Instructions for updating:
Use standard file APIs to check for files with this prefix.
W0609 10:07:55.909765 140324213704512 deprecation.py:323] From /Midgard/home/ppoklukar/anaconda3/lib/python3.7/site-packages/tensorflow/python/training/saver.py:1276: checkpoint_exists (from tensorflow.python.training.checkpoint_management) is deprecated and will be removed in a future version.
Instructions for updating:
Use standard file APIs to check for files with this prefix.
INFO:tensorflow:Restoring parameters from 3dshapes_models/vae3dshapes_model_s1000_1602/model/tf_checkpoint/model.ckpt-5
I0609 10:07:55.911197 140324213704512 saver.py:1280] Restoring parameters from 3dshapes_models/vae3dshapes_model_s1000_1602/model/tf_checkpoint/model.ckpt-5
INFO:tensorflow:Running local_init_op.
I0609 10:07:56.013337 140324213704512 session_manager.py:500] Running local_init_op.
INFO:tensorflow:Done running local_init_op.
I0609 10:07:56.042166 140324213704512 session_manager.py:502] Done running local_init_op.
INFO:tensorflow:Finished evaluation at 2020-06-09-10:08:46
I0609 10:08:46.396519 140324213704512 evaluation.py:275] Finished evaluation at 2020-06-09-10:08:46
INFO:tensorflow:Saving dict for global step 5: elbo = -1934.3112, global_step = 5, kl_loss = 0.009017354, loss = 1934.3112, reconstruction_loss = 1934.3013, regularizer = 0.009017354
I0609 10:08:46.397447 140324213704512 estimator.py:2039] Saving dict for global step 5: elbo = -1934.3112, global_step = 5, kl_loss = 0.009017354, loss = 1934.3112, reconstruction_loss = 1934.3013, regularizer = 0.009017354
INFO:tensorflow:Saving 'checkpoint_path' summary for global step 5: 3dshapes_models/vae3dshapes_model_s1000_1602/model/tf_checkpoint/model.ckpt-5
I0609 10:08:46.477573 140324213704512 estimator.py:2099] Saving 'checkpoint_path' summary for global step 5: 3dshapes_models/vae3dshapes_model_s1000_1602/model/tf_checkpoint/model.ckpt-5
INFO:tensorflow:evaluation_loop marked as finished
I0609 10:08:46.478371 140324213704512 error_handling.py:96] evaluation_loop marked as finished
WARNING:tensorflow:From ../disentanglement_lib/utils/results.py:61: The name tf.gfile.MakeDirs is deprecated. Please use tf.io.gfile.makedirs instead.

W0609 10:08:46.478961 140324213704512 deprecation_wrapper.py:119] From ../disentanglement_lib/utils/results.py:61: The name tf.gfile.MakeDirs is deprecated. Please use tf.io.gfile.makedirs instead.

WARNING:tensorflow:From ../disentanglement_lib/utils/results.py:115: The name tf.gfile.GFile is deprecated. Please use tf.io.gfile.GFile instead.

W0609 10:08:46.480030 140324213704512 deprecation_wrapper.py:119] From ../disentanglement_lib/utils/results.py:115: The name tf.gfile.GFile is deprecated. Please use tf.io.gfile.GFile instead.

WARNING:tensorflow:From ../disentanglement_lib/utils/results.py:216: The name tf.gfile.ListDirectory is deprecated. Please use tf.io.gfile.listdir instead.

W0609 10:08:46.486523 140324213704512 deprecation_wrapper.py:119] From ../disentanglement_lib/utils/results.py:216: The name tf.gfile.ListDirectory is deprecated. Please use tf.io.gfile.listdir instead.

INFO:tensorflow:Saver not created because there are no variables in the graph to restore
I0609 10:08:46.842539 140324213704512 saver.py:1499] Saver not created because there are no variables in the graph to restore
INFO:tensorflow:Saver not created because there are no variables in the graph to restore
I0609 10:08:46.950405 140324213704512 saver.py:1499] Saver not created because there are no variables in the graph to restore
INFO:tensorflow:Saver not created because there are no variables in the graph to restore
I0609 10:08:47.204127 140324213704512 saver.py:1499] Saver not created because there are no variables in the graph to restore
INFO:tensorflow:Graph was finalized.
I0609 10:08:47.334801 140324213704512 monitored_session.py:240] Graph was finalized.
2020-06-09 10:08:47.335321: I tensorflow/core/common_runtime/gpu/gpu_device.cc:1181] Device interconnect StreamExecutor with strength 1 edge matrix:
2020-06-09 10:08:47.335363: I tensorflow/core/common_runtime/gpu/gpu_device.cc:1187]      
INFO:tensorflow:Running local_init_op.
I0609 10:08:47.526528 140324213704512 session_manager.py:500] Running local_init_op.
INFO:tensorflow:Done running local_init_op.
I0609 10:08:47.547766 140324213704512 session_manager.py:502] Done running local_init_op.
INFO:tensorflow:Saver not created because there are no variables in the graph to restore
I0609 10:08:47.932551 140324213704512 saver.py:1499] Saver not created because there are no variables in the graph to restore
2020-06-09 10:08:48.466262: I tensorflow/core/common_runtime/gpu/gpu_device.cc:1181] Device interconnect StreamExecutor with strength 1 edge matrix:
2020-06-09 10:08:48.466328: I tensorflow/core/common_runtime/gpu/gpu_device.cc:1187]      
I0609 10:08:48.687104 140324213704512 native_module.py:405] Exported TF-Hub module to: 3dshapes_models/vae3dshapes_model_s1000_1602/representation/tfhub
INFO:tensorflow:Saver not created because there are no variables in the graph to restore
I0609 10:09:42.957627 140324213704512 saver.py:1499] Saver not created because there are no variables in the graph to restore
INFO:tensorflow:Graph was finalized.
I0609 10:09:43.112553 140324213704512 monitored_session.py:240] Graph was finalized.
2020-06-09 10:09:43.113147: I tensorflow/core/common_runtime/gpu/gpu_device.cc:1181] Device interconnect StreamExecutor with strength 1 edge matrix:
2020-06-09 10:09:43.113187: I tensorflow/core/common_runtime/gpu/gpu_device.cc:1187]      
INFO:tensorflow:Running local_init_op.
I0609 10:09:43.328659 140324213704512 session_manager.py:500] Running local_init_op.
INFO:tensorflow:Done running local_init_op.
I0609 10:09:43.354974 140324213704512 session_manager.py:502] Done running local_init_op.
/Midgard/home/ppoklukar/anaconda3/lib/python3.7/site-packages/sklearn/neural_network/multilayer_perceptron.py:566: ConvergenceWarning: Stochastic Optimizer: Maximum iterations (100) reached and the optimization hasn't converged yet.
  % self.max_iter, ConvergenceWarning)
INFO:tensorflow:Saver not created because there are no variables in the graph to restore
I0609 10:10:23.055714 140324213704512 saver.py:1499] Saver not created because there are no variables in the graph to restore
INFO:tensorflow:Graph was finalized.
I0609 10:10:23.210199 140324213704512 monitored_session.py:240] Graph was finalized.
2020-06-09 10:10:23.210754: I tensorflow/core/common_runtime/gpu/gpu_device.cc:1181] Device interconnect StreamExecutor with strength 1 edge matrix:
2020-06-09 10:10:23.210794: I tensorflow/core/common_runtime/gpu/gpu_device.cc:1187]      
INFO:tensorflow:Running local_init_op.
I0609 10:10:23.399293 140324213704512 session_manager.py:500] Running local_init_op.
INFO:tensorflow:Done running local_init_op.
I0609 10:10:23.431325 140324213704512 session_manager.py:502] Done running local_init_op.
WARNING:tensorflow:Estimator's model_fn (<bound method Decoder.model_fn of <disentanglement_lib.methods.supervised.decoder.Decoder object at 0x7f9f45bc0208>>) includes params argument, but params are not passed to Estimator.
W0609 10:10:23.480362 140324213704512 estimator.py:1984] Estimator's model_fn (<bound method Decoder.model_fn of <disentanglement_lib.methods.supervised.decoder.Decoder object at 0x7f9f45bc0208>>) includes params argument, but params are not passed to Estimator.
INFO:tensorflow:Using config: {'_model_dir': '3dshapes_models/vae3dshapes_model_s1000_1602/metrics/reconstruction/tf_checkpoint', '_tf_random_seed': 1602, '_save_summary_steps': 100, '_save_checkpoints_steps': None, '_save_checkpoints_secs': 600, '_session_config': allow_soft_placement: true
graph_options {
  rewrite_options {
    meta_optimizer_iterations: ONE
  }
}
, '_keep_checkpoint_max': 1, '_keep_checkpoint_every_n_hours': 10000, '_log_step_count_steps': None, '_train_distribute': None, '_device_fn': None, '_protocol': None, '_eval_distribute': None, '_experimental_distribute': None, '_experimental_max_worker_delay_secs': None, '_service': None, '_cluster_spec': <tensorflow.python.training.server_lib.ClusterSpec object at 0x7f9f71afe550>, '_task_type': 'worker', '_task_id': 0, '_global_id_in_cluster': 0, '_master': '', '_evaluation_master': '', '_is_chief': True, '_num_ps_replicas': 0, '_num_worker_replicas': 1, '_tpu_config': TPUConfig(iterations_per_loop=500, num_shards=None, num_cores_per_replica=None, per_host_input_for_training=2, tpu_job_name=None, initial_infeed_sleep_secs=None, input_partition_dims=None, eval_training_input_configuration=2), '_cluster': None}
I0609 10:10:23.481103 140324213704512 estimator.py:209] Using config: {'_model_dir': '3dshapes_models/vae3dshapes_model_s1000_1602/metrics/reconstruction/tf_checkpoint', '_tf_random_seed': 1602, '_save_summary_steps': 100, '_save_checkpoints_steps': None, '_save_checkpoints_secs': 600, '_session_config': allow_soft_placement: true
graph_options {
  rewrite_options {
    meta_optimizer_iterations: ONE
  }
}
, '_keep_checkpoint_max': 1, '_keep_checkpoint_every_n_hours': 10000, '_log_step_count_steps': None, '_train_distribute': None, '_device_fn': None, '_protocol': None, '_eval_distribute': None, '_experimental_distribute': None, '_experimental_max_worker_delay_secs': None, '_service': None, '_cluster_spec': <tensorflow.python.training.server_lib.ClusterSpec object at 0x7f9f71afe550>, '_task_type': 'worker', '_task_id': 0, '_global_id_in_cluster': 0, '_master': '', '_evaluation_master': '', '_is_chief': True, '_num_ps_replicas': 0, '_num_worker_replicas': 1, '_tpu_config': TPUConfig(iterations_per_loop=500, num_shards=None, num_cores_per_replica=None, per_host_input_for_training=2, tpu_job_name=None, initial_infeed_sleep_secs=None, input_partition_dims=None, eval_training_input_configuration=2), '_cluster': None}
INFO:tensorflow:_TPUContext: eval_on_tpu True
I0609 10:10:23.481343 140324213704512 tpu_context.py:209] _TPUContext: eval_on_tpu True
WARNING:tensorflow:eval_on_tpu ignored because use_tpu is False.
W0609 10:10:23.481431 140324213704512 tpu_context.py:211] eval_on_tpu ignored because use_tpu is False.
INFO:tensorflow:Calling model_fn.
I0609 10:10:23.521747 140324213704512 estimator.py:1145] Calling model_fn.
INFO:tensorflow:Running train on CPU
I0609 10:10:23.521970 140324213704512 tpu_estimator.py:2965] Running train on CPU
WARNING:tensorflow:Entity <bound method Dense.call of <tensorflow.python.layers.core.Dense object at 0x7f9f45e2c438>> could not be transformed and will be executed as-is. Please report this to the AutgoGraph team. When filing the bug, set the verbosity to 10 (on Linux, `export AUTOGRAPH_VERBOSITY=10`) and attach the full output. Cause: converting <bound method Dense.call of <tensorflow.python.layers.core.Dense object at 0x7f9f45e2c438>>: AssertionError: Bad argument number for Name: 3, expecting 4
W0609 10:10:23.617216 140324213704512 ag_logging.py:145] Entity <bound method Dense.call of <tensorflow.python.layers.core.Dense object at 0x7f9f45e2c438>> could not be transformed and will be executed as-is. Please report this to the AutgoGraph team. When filing the bug, set the verbosity to 10 (on Linux, `export AUTOGRAPH_VERBOSITY=10`) and attach the full output. Cause: converting <bound method Dense.call of <tensorflow.python.layers.core.Dense object at 0x7f9f45e2c438>>: AssertionError: Bad argument number for Name: 3, expecting 4
WARNING:tensorflow:Entity <bound method Dense.call of <tensorflow.python.layers.core.Dense object at 0x7f9f4cecea58>> could not be transformed and will be executed as-is. Please report this to the AutgoGraph team. When filing the bug, set the verbosity to 10 (on Linux, `export AUTOGRAPH_VERBOSITY=10`) and attach the full output. Cause: converting <bound method Dense.call of <tensorflow.python.layers.core.Dense object at 0x7f9f4cecea58>>: AssertionError: Bad argument number for Name: 3, expecting 4
W0609 10:10:23.714644 140324213704512 ag_logging.py:145] Entity <bound method Dense.call of <tensorflow.python.layers.core.Dense object at 0x7f9f4cecea58>> could not be transformed and will be executed as-is. Please report this to the AutgoGraph team. When filing the bug, set the verbosity to 10 (on Linux, `export AUTOGRAPH_VERBOSITY=10`) and attach the full output. Cause: converting <bound method Dense.call of <tensorflow.python.layers.core.Dense object at 0x7f9f4cecea58>>: AssertionError: Bad argument number for Name: 3, expecting 4
WARNING:tensorflow:Entity <bound method Conv2DTranspose.call of <tensorflow.python.layers.convolutional.Conv2DTranspose object at 0x7f9f718e8908>> could not be transformed and will be executed as-is. Please report this to the AutgoGraph team. When filing the bug, set the verbosity to 10 (on Linux, `export AUTOGRAPH_VERBOSITY=10`) and attach the full output. Cause: converting <bound method Conv2DTranspose.call of <tensorflow.python.layers.convolutional.Conv2DTranspose object at 0x7f9f718e8908>>: AttributeError: module 'gast' has no attribute 'Num'
W0609 10:10:23.748052 140324213704512 ag_logging.py:145] Entity <bound method Conv2DTranspose.call of <tensorflow.python.layers.convolutional.Conv2DTranspose object at 0x7f9f718e8908>> could not be transformed and will be executed as-is. Please report this to the AutgoGraph team. When filing the bug, set the verbosity to 10 (on Linux, `export AUTOGRAPH_VERBOSITY=10`) and attach the full output. Cause: converting <bound method Conv2DTranspose.call of <tensorflow.python.layers.convolutional.Conv2DTranspose object at 0x7f9f718e8908>>: AttributeError: module 'gast' has no attribute 'Num'
WARNING:tensorflow:Entity <bound method Conv2DTranspose.call of <tensorflow.python.layers.convolutional.Conv2DTranspose object at 0x7f9f718e8908>> could not be transformed and will be executed as-is. Please report this to the AutgoGraph team. When filing the bug, set the verbosity to 10 (on Linux, `export AUTOGRAPH_VERBOSITY=10`) and attach the full output. Cause: converting <bound method Conv2DTranspose.call of <tensorflow.python.layers.convolutional.Conv2DTranspose object at 0x7f9f718e8908>>: AttributeError: module 'gast' has no attribute 'Num'
W0609 10:10:23.798824 140324213704512 ag_logging.py:145] Entity <bound method Conv2DTranspose.call of <tensorflow.python.layers.convolutional.Conv2DTranspose object at 0x7f9f718e8908>> could not be transformed and will be executed as-is. Please report this to the AutgoGraph team. When filing the bug, set the verbosity to 10 (on Linux, `export AUTOGRAPH_VERBOSITY=10`) and attach the full output. Cause: converting <bound method Conv2DTranspose.call of <tensorflow.python.layers.convolutional.Conv2DTranspose object at 0x7f9f718e8908>>: AttributeError: module 'gast' has no attribute 'Num'
WARNING:tensorflow:Entity <bound method Conv2DTranspose.call of <tensorflow.python.layers.convolutional.Conv2DTranspose object at 0x7f9f718e8908>> could not be transformed and will be executed as-is. Please report this to the AutgoGraph team. When filing the bug, set the verbosity to 10 (on Linux, `export AUTOGRAPH_VERBOSITY=10`) and attach the full output. Cause: converting <bound method Conv2DTranspose.call of <tensorflow.python.layers.convolutional.Conv2DTranspose object at 0x7f9f718e8908>>: AttributeError: module 'gast' has no attribute 'Num'
W0609 10:10:23.845789 140324213704512 ag_logging.py:145] Entity <bound method Conv2DTranspose.call of <tensorflow.python.layers.convolutional.Conv2DTranspose object at 0x7f9f718e8908>> could not be transformed and will be executed as-is. Please report this to the AutgoGraph team. When filing the bug, set the verbosity to 10 (on Linux, `export AUTOGRAPH_VERBOSITY=10`) and attach the full output. Cause: converting <bound method Conv2DTranspose.call of <tensorflow.python.layers.convolutional.Conv2DTranspose object at 0x7f9f718e8908>>: AttributeError: module 'gast' has no attribute 'Num'
WARNING:tensorflow:Entity <bound method Conv2DTranspose.call of <tensorflow.python.layers.convolutional.Conv2DTranspose object at 0x7f9f718e8908>> could not be transformed and will be executed as-is. Please report this to the AutgoGraph team. When filing the bug, set the verbosity to 10 (on Linux, `export AUTOGRAPH_VERBOSITY=10`) and attach the full output. Cause: converting <bound method Conv2DTranspose.call of <tensorflow.python.layers.convolutional.Conv2DTranspose object at 0x7f9f718e8908>>: AttributeError: module 'gast' has no attribute 'Num'
W0609 10:10:23.991040 140324213704512 ag_logging.py:145] Entity <bound method Conv2DTranspose.call of <tensorflow.python.layers.convolutional.Conv2DTranspose object at 0x7f9f718e8908>> could not be transformed and will be executed as-is. Please report this to the AutgoGraph team. When filing the bug, set the verbosity to 10 (on Linux, `export AUTOGRAPH_VERBOSITY=10`) and attach the full output. Cause: converting <bound method Conv2DTranspose.call of <tensorflow.python.layers.convolutional.Conv2DTranspose object at 0x7f9f718e8908>>: AttributeError: module 'gast' has no attribute 'Num'
INFO:tensorflow:Done calling model_fn.
I0609 10:10:24.225363 140324213704512 estimator.py:1147] Done calling model_fn.
INFO:tensorflow:Create CheckpointSaverHook.
I0609 10:10:24.226636 140324213704512 basic_session_run_hooks.py:541] Create CheckpointSaverHook.
INFO:tensorflow:Graph was finalized.
I0609 10:10:24.421588 140324213704512 monitored_session.py:240] Graph was finalized.
2020-06-09 10:10:24.423472: I tensorflow/core/common_runtime/gpu/gpu_device.cc:1640] Found device 0 with properties: 
name: GeForce GTX 1080 Ti major: 6 minor: 1 memoryClockRate(GHz): 1.62
pciBusID: 0000:81:00.0
2020-06-09 10:10:24.423547: I tensorflow/stream_executor/platform/default/dso_loader.cc:42] Successfully opened dynamic library libcudart.so.10.0
2020-06-09 10:10:24.423573: I tensorflow/stream_executor/platform/default/dso_loader.cc:42] Successfully opened dynamic library libcublas.so.10.0
2020-06-09 10:10:24.423596: I tensorflow/stream_executor/platform/default/dso_loader.cc:42] Successfully opened dynamic library libcufft.so.10.0
2020-06-09 10:10:24.423619: I tensorflow/stream_executor/platform/default/dso_loader.cc:42] Successfully opened dynamic library libcurand.so.10.0
2020-06-09 10:10:24.423640: I tensorflow/stream_executor/platform/default/dso_loader.cc:42] Successfully opened dynamic library libcusolver.so.10.0
2020-06-09 10:10:24.423661: I tensorflow/stream_executor/platform/default/dso_loader.cc:42] Successfully opened dynamic library libcusparse.so.10.0
2020-06-09 10:10:24.424075: I tensorflow/stream_executor/platform/default/dso_loader.cc:53] Could not dlopen library 'libcudnn.so.7'; dlerror: libcudnn.so.7: cannot open shared object file: No such file or directory
2020-06-09 10:10:24.424088: W tensorflow/core/common_runtime/gpu/gpu_device.cc:1663] Cannot dlopen some GPU libraries. Skipping registering GPU devices...
2020-06-09 10:10:24.424105: I tensorflow/core/common_runtime/gpu/gpu_device.cc:1181] Device interconnect StreamExecutor with strength 1 edge matrix:
2020-06-09 10:10:24.424112: I tensorflow/core/common_runtime/gpu/gpu_device.cc:1187]      0 
2020-06-09 10:10:24.424118: I tensorflow/core/common_runtime/gpu/gpu_device.cc:1200] 0:   N 
INFO:tensorflow:Running local_init_op.
I0609 10:10:24.552007 140324213704512 session_manager.py:500] Running local_init_op.
INFO:tensorflow:Done running local_init_op.
I0609 10:10:24.560553 140324213704512 session_manager.py:502] Done running local_init_op.
INFO:tensorflow:Saving checkpoints for 0 into 3dshapes_models/vae3dshapes_model_s1000_1602/metrics/reconstruction/tf_checkpoint/model.ckpt.
I0609 10:10:24.885425 140324213704512 basic_session_run_hooks.py:606] Saving checkpoints for 0 into 3dshapes_models/vae3dshapes_model_s1000_1602/metrics/reconstruction/tf_checkpoint/model.ckpt.
INFO:tensorflow:reconstruction_loss = 1903.3296
I0609 10:10:25.386251 140324213704512 basic_session_run_hooks.py:262] reconstruction_loss = 1903.3296
INFO:tensorflow:global_step/sec: 3.46724
I0609 10:10:25.675339 140324213704512 tpu_estimator.py:2159] global_step/sec: 3.46724
INFO:tensorflow:examples/sec: 221.903
I0609 10:10:25.675620 140324213704512 tpu_estimator.py:2160] examples/sec: 221.903
INFO:tensorflow:global_step/sec: 6.19316
I0609 10:10:25.836811 140324213704512 tpu_estimator.py:2159] global_step/sec: 6.19316
INFO:tensorflow:examples/sec: 396.362
I0609 10:10:25.837134 140324213704512 tpu_estimator.py:2160] examples/sec: 396.362
INFO:tensorflow:global_step/sec: 5.93289
I0609 10:10:26.005384 140324213704512 tpu_estimator.py:2159] global_step/sec: 5.93289
INFO:tensorflow:examples/sec: 379.705
I0609 10:10:26.005690 140324213704512 tpu_estimator.py:2160] examples/sec: 379.705
INFO:tensorflow:global_step/sec: 6.02004
I0609 10:10:26.171482 140324213704512 tpu_estimator.py:2159] global_step/sec: 6.02004
INFO:tensorflow:examples/sec: 385.282
I0609 10:10:26.171780 140324213704512 tpu_estimator.py:2160] examples/sec: 385.282
INFO:tensorflow:Saving checkpoints for 5 into 3dshapes_models/vae3dshapes_model_s1000_1602/metrics/reconstruction/tf_checkpoint/model.ckpt.
I0609 10:10:26.172093 140324213704512 basic_session_run_hooks.py:606] Saving checkpoints for 5 into 3dshapes_models/vae3dshapes_model_s1000_1602/metrics/reconstruction/tf_checkpoint/model.ckpt.
INFO:tensorflow:Loss for final step: 1941.4348.
I0609 10:10:26.297658 140324213704512 estimator.py:368] Loss for final step: 1941.4348.
INFO:tensorflow:training_loop marked as finished
I0609 10:10:26.297969 140324213704512 error_handling.py:96] training_loop marked as finished
WARNING:tensorflow:Entity <bound method Dense.call of <tensorflow.python.layers.core.Dense object at 0x7f9f71afe8d0>> could not be transformed and will be executed as-is. Please report this to the AutgoGraph team. When filing the bug, set the verbosity to 10 (on Linux, `export AUTOGRAPH_VERBOSITY=10`) and attach the full output. Cause: converting <bound method Dense.call of <tensorflow.python.layers.core.Dense object at 0x7f9f71afe8d0>>: AssertionError: Bad argument number for Name: 3, expecting 4
W0609 10:11:04.646985 140324213704512 ag_logging.py:145] Entity <bound method Dense.call of <tensorflow.python.layers.core.Dense object at 0x7f9f71afe8d0>> could not be transformed and will be executed as-is. Please report this to the AutgoGraph team. When filing the bug, set the verbosity to 10 (on Linux, `export AUTOGRAPH_VERBOSITY=10`) and attach the full output. Cause: converting <bound method Dense.call of <tensorflow.python.layers.core.Dense object at 0x7f9f71afe8d0>>: AssertionError: Bad argument number for Name: 3, expecting 4
WARNING:tensorflow:Entity <bound method Dense.call of <tensorflow.python.layers.core.Dense object at 0x7f9f71afe8d0>> could not be transformed and will be executed as-is. Please report this to the AutgoGraph team. When filing the bug, set the verbosity to 10 (on Linux, `export AUTOGRAPH_VERBOSITY=10`) and attach the full output. Cause: converting <bound method Dense.call of <tensorflow.python.layers.core.Dense object at 0x7f9f71afe8d0>>: AssertionError: Bad argument number for Name: 3, expecting 4
W0609 10:11:04.747792 140324213704512 ag_logging.py:145] Entity <bound method Dense.call of <tensorflow.python.layers.core.Dense object at 0x7f9f71afe8d0>> could not be transformed and will be executed as-is. Please report this to the AutgoGraph team. When filing the bug, set the verbosity to 10 (on Linux, `export AUTOGRAPH_VERBOSITY=10`) and attach the full output. Cause: converting <bound method Dense.call of <tensorflow.python.layers.core.Dense object at 0x7f9f71afe8d0>>: AssertionError: Bad argument number for Name: 3, expecting 4
WARNING:tensorflow:Entity <bound method Conv2DTranspose.call of <tensorflow.python.layers.convolutional.Conv2DTranspose object at 0x7f9f71afe8d0>> could not be transformed and will be executed as-is. Please report this to the AutgoGraph team. When filing the bug, set the verbosity to 10 (on Linux, `export AUTOGRAPH_VERBOSITY=10`) and attach the full output. Cause: converting <bound method Conv2DTranspose.call of <tensorflow.python.layers.convolutional.Conv2DTranspose object at 0x7f9f71afe8d0>>: AttributeError: module 'gast' has no attribute 'Num'
W0609 10:11:04.783262 140324213704512 ag_logging.py:145] Entity <bound method Conv2DTranspose.call of <tensorflow.python.layers.convolutional.Conv2DTranspose object at 0x7f9f71afe8d0>> could not be transformed and will be executed as-is. Please report this to the AutgoGraph team. When filing the bug, set the verbosity to 10 (on Linux, `export AUTOGRAPH_VERBOSITY=10`) and attach the full output. Cause: converting <bound method Conv2DTranspose.call of <tensorflow.python.layers.convolutional.Conv2DTranspose object at 0x7f9f71afe8d0>>: AttributeError: module 'gast' has no attribute 'Num'
WARNING:tensorflow:Entity <bound method Conv2DTranspose.call of <tensorflow.python.layers.convolutional.Conv2DTranspose object at 0x7f9f71afe8d0>> could not be transformed and will be executed as-is. Please report this to the AutgoGraph team. When filing the bug, set the verbosity to 10 (on Linux, `export AUTOGRAPH_VERBOSITY=10`) and attach the full output. Cause: converting <bound method Conv2DTranspose.call of <tensorflow.python.layers.convolutional.Conv2DTranspose object at 0x7f9f71afe8d0>>: AttributeError: module 'gast' has no attribute 'Num'
W0609 10:11:04.831814 140324213704512 ag_logging.py:145] Entity <bound method Conv2DTranspose.call of <tensorflow.python.layers.convolutional.Conv2DTranspose object at 0x7f9f71afe8d0>> could not be transformed and will be executed as-is. Please report this to the AutgoGraph team. When filing the bug, set the verbosity to 10 (on Linux, `export AUTOGRAPH_VERBOSITY=10`) and attach the full output. Cause: converting <bound method Conv2DTranspose.call of <tensorflow.python.layers.convolutional.Conv2DTranspose object at 0x7f9f71afe8d0>>: AttributeError: module 'gast' has no attribute 'Num'
WARNING:tensorflow:Entity <bound method Conv2DTranspose.call of <tensorflow.python.layers.convolutional.Conv2DTranspose object at 0x7f9f71afe8d0>> could not be transformed and will be executed as-is. Please report this to the AutgoGraph team. When filing the bug, set the verbosity to 10 (on Linux, `export AUTOGRAPH_VERBOSITY=10`) and attach the full output. Cause: converting <bound method Conv2DTranspose.call of <tensorflow.python.layers.convolutional.Conv2DTranspose object at 0x7f9f71afe8d0>>: AttributeError: module 'gast' has no attribute 'Num'
W0609 10:11:04.882130 140324213704512 ag_logging.py:145] Entity <bound method Conv2DTranspose.call of <tensorflow.python.layers.convolutional.Conv2DTranspose object at 0x7f9f71afe8d0>> could not be transformed and will be executed as-is. Please report this to the AutgoGraph team. When filing the bug, set the verbosity to 10 (on Linux, `export AUTOGRAPH_VERBOSITY=10`) and attach the full output. Cause: converting <bound method Conv2DTranspose.call of <tensorflow.python.layers.convolutional.Conv2DTranspose object at 0x7f9f71afe8d0>>: AttributeError: module 'gast' has no attribute 'Num'
WARNING:tensorflow:Entity <bound method Conv2DTranspose.call of <tensorflow.python.layers.convolutional.Conv2DTranspose object at 0x7f9f71afe8d0>> could not be transformed and will be executed as-is. Please report this to the AutgoGraph team. When filing the bug, set the verbosity to 10 (on Linux, `export AUTOGRAPH_VERBOSITY=10`) and attach the full output. Cause: converting <bound method Conv2DTranspose.call of <tensorflow.python.layers.convolutional.Conv2DTranspose object at 0x7f9f71afe8d0>>: AttributeError: module 'gast' has no attribute 'Num'
W0609 10:11:04.930586 140324213704512 ag_logging.py:145] Entity <bound method Conv2DTranspose.call of <tensorflow.python.layers.convolutional.Conv2DTranspose object at 0x7f9f71afe8d0>> could not be transformed and will be executed as-is. Please report this to the AutgoGraph team. When filing the bug, set the verbosity to 10 (on Linux, `export AUTOGRAPH_VERBOSITY=10`) and attach the full output. Cause: converting <bound method Conv2DTranspose.call of <tensorflow.python.layers.convolutional.Conv2DTranspose object at 0x7f9f71afe8d0>>: AttributeError: module 'gast' has no attribute 'Num'
WARNING:tensorflow:Entity <bound method Dense.call of <tensorflow.python.layers.core.Dense object at 0x7f9f71c54c18>> could not be transformed and will be executed as-is. Please report this to the AutgoGraph team. When filing the bug, set the verbosity to 10 (on Linux, `export AUTOGRAPH_VERBOSITY=10`) and attach the full output. Cause: converting <bound method Dense.call of <tensorflow.python.layers.core.Dense object at 0x7f9f71c54c18>>: AssertionError: Bad argument number for Name: 3, expecting 4
W0609 10:11:05.066892 140324213704512 ag_logging.py:145] Entity <bound method Dense.call of <tensorflow.python.layers.core.Dense object at 0x7f9f71c54c18>> could not be transformed and will be executed as-is. Please report this to the AutgoGraph team. When filing the bug, set the verbosity to 10 (on Linux, `export AUTOGRAPH_VERBOSITY=10`) and attach the full output. Cause: converting <bound method Dense.call of <tensorflow.python.layers.core.Dense object at 0x7f9f71c54c18>>: AssertionError: Bad argument number for Name: 3, expecting 4
WARNING:tensorflow:Entity <bound method Dense.call of <tensorflow.python.layers.core.Dense object at 0x7f9f45cfcf60>> could not be transformed and will be executed as-is. Please report this to the AutgoGraph team. When filing the bug, set the verbosity to 10 (on Linux, `export AUTOGRAPH_VERBOSITY=10`) and attach the full output. Cause: converting <bound method Dense.call of <tensorflow.python.layers.core.Dense object at 0x7f9f45cfcf60>>: AssertionError: Bad argument number for Name: 3, expecting 4
W0609 10:11:05.165250 140324213704512 ag_logging.py:145] Entity <bound method Dense.call of <tensorflow.python.layers.core.Dense object at 0x7f9f45cfcf60>> could not be transformed and will be executed as-is. Please report this to the AutgoGraph team. When filing the bug, set the verbosity to 10 (on Linux, `export AUTOGRAPH_VERBOSITY=10`) and attach the full output. Cause: converting <bound method Dense.call of <tensorflow.python.layers.core.Dense object at 0x7f9f45cfcf60>>: AssertionError: Bad argument number for Name: 3, expecting 4
WARNING:tensorflow:Entity <bound method Conv2DTranspose.call of <tensorflow.python.layers.convolutional.Conv2DTranspose object at 0x7f9f71c4e278>> could not be transformed and will be executed as-is. Please report this to the AutgoGraph team. When filing the bug, set the verbosity to 10 (on Linux, `export AUTOGRAPH_VERBOSITY=10`) and attach the full output. Cause: converting <bound method Conv2DTranspose.call of <tensorflow.python.layers.convolutional.Conv2DTranspose object at 0x7f9f71c4e278>>: AttributeError: module 'gast' has no attribute 'Num'
W0609 10:11:05.200735 140324213704512 ag_logging.py:145] Entity <bound method Conv2DTranspose.call of <tensorflow.python.layers.convolutional.Conv2DTranspose object at 0x7f9f71c4e278>> could not be transformed and will be executed as-is. Please report this to the AutgoGraph team. When filing the bug, set the verbosity to 10 (on Linux, `export AUTOGRAPH_VERBOSITY=10`) and attach the full output. Cause: converting <bound method Conv2DTranspose.call of <tensorflow.python.layers.convolutional.Conv2DTranspose object at 0x7f9f71c4e278>>: AttributeError: module 'gast' has no attribute 'Num'
WARNING:tensorflow:Entity <bound method Conv2DTranspose.call of <tensorflow.python.layers.convolutional.Conv2DTranspose object at 0x7f9f71c4e278>> could not be transformed and will be executed as-is. Please report this to the AutgoGraph team. When filing the bug, set the verbosity to 10 (on Linux, `export AUTOGRAPH_VERBOSITY=10`) and attach the full output. Cause: converting <bound method Conv2DTranspose.call of <tensorflow.python.layers.convolutional.Conv2DTranspose object at 0x7f9f71c4e278>>: AttributeError: module 'gast' has no attribute 'Num'
W0609 10:11:05.249162 140324213704512 ag_logging.py:145] Entity <bound method Conv2DTranspose.call of <tensorflow.python.layers.convolutional.Conv2DTranspose object at 0x7f9f71c4e278>> could not be transformed and will be executed as-is. Please report this to the AutgoGraph team. When filing the bug, set the verbosity to 10 (on Linux, `export AUTOGRAPH_VERBOSITY=10`) and attach the full output. Cause: converting <bound method Conv2DTranspose.call of <tensorflow.python.layers.convolutional.Conv2DTranspose object at 0x7f9f71c4e278>>: AttributeError: module 'gast' has no attribute 'Num'
WARNING:tensorflow:Entity <bound method Conv2DTranspose.call of <tensorflow.python.layers.convolutional.Conv2DTranspose object at 0x7f9f71c4e278>> could not be transformed and will be executed as-is. Please report this to the AutgoGraph team. When filing the bug, set the verbosity to 10 (on Linux, `export AUTOGRAPH_VERBOSITY=10`) and attach the full output. Cause: converting <bound method Conv2DTranspose.call of <tensorflow.python.layers.convolutional.Conv2DTranspose object at 0x7f9f71c4e278>>: AttributeError: module 'gast' has no attribute 'Num'
W0609 10:11:05.297113 140324213704512 ag_logging.py:145] Entity <bound method Conv2DTranspose.call of <tensorflow.python.layers.convolutional.Conv2DTranspose object at 0x7f9f71c4e278>> could not be transformed and will be executed as-is. Please report this to the AutgoGraph team. When filing the bug, set the verbosity to 10 (on Linux, `export AUTOGRAPH_VERBOSITY=10`) and attach the full output. Cause: converting <bound method Conv2DTranspose.call of <tensorflow.python.layers.convolutional.Conv2DTranspose object at 0x7f9f71c4e278>>: AttributeError: module 'gast' has no attribute 'Num'
WARNING:tensorflow:Entity <bound method Conv2DTranspose.call of <tensorflow.python.layers.convolutional.Conv2DTranspose object at 0x7f9f71c4e278>> could not be transformed and will be executed as-is. Please report this to the AutgoGraph team. When filing the bug, set the verbosity to 10 (on Linux, `export AUTOGRAPH_VERBOSITY=10`) and attach the full output. Cause: converting <bound method Conv2DTranspose.call of <tensorflow.python.layers.convolutional.Conv2DTranspose object at 0x7f9f71c4e278>>: AttributeError: module 'gast' has no attribute 'Num'
W0609 10:11:05.345365 140324213704512 ag_logging.py:145] Entity <bound method Conv2DTranspose.call of <tensorflow.python.layers.convolutional.Conv2DTranspose object at 0x7f9f71c4e278>> could not be transformed and will be executed as-is. Please report this to the AutgoGraph team. When filing the bug, set the verbosity to 10 (on Linux, `export AUTOGRAPH_VERBOSITY=10`) and attach the full output. Cause: converting <bound method Conv2DTranspose.call of <tensorflow.python.layers.convolutional.Conv2DTranspose object at 0x7f9f71c4e278>>: AttributeError: module 'gast' has no attribute 'Num'
2020-06-09 10:11:05.529286: I tensorflow/core/common_runtime/gpu/gpu_device.cc:1181] Device interconnect StreamExecutor with strength 1 edge matrix:
2020-06-09 10:11:05.529340: I tensorflow/core/common_runtime/gpu/gpu_device.cc:1187]      
I0609 10:11:05.682142 140324213704512 native_module.py:405] Exported TF-Hub module to: 3dshapes_models/vae3dshapes_model_s1000_1602/metrics/reconstruction/tfhub
INFO:tensorflow:Calling model_fn.
I0609 10:11:05.726882 140324213704512 estimator.py:1145] Calling model_fn.
INFO:tensorflow:Running eval on CPU
I0609 10:11:05.727097 140324213704512 tpu_estimator.py:2965] Running eval on CPU
WARNING:tensorflow:Entity <bound method Dense.call of <tensorflow.python.layers.core.Dense object at 0x7f9f4cef41d0>> could not be transformed and will be executed as-is. Please report this to the AutgoGraph team. When filing the bug, set the verbosity to 10 (on Linux, `export AUTOGRAPH_VERBOSITY=10`) and attach the full output. Cause: converting <bound method Dense.call of <tensorflow.python.layers.core.Dense object at 0x7f9f4cef41d0>>: AssertionError: Bad argument number for Name: 3, expecting 4
W0609 10:11:05.821923 140324213704512 ag_logging.py:145] Entity <bound method Dense.call of <tensorflow.python.layers.core.Dense object at 0x7f9f4cef41d0>> could not be transformed and will be executed as-is. Please report this to the AutgoGraph team. When filing the bug, set the verbosity to 10 (on Linux, `export AUTOGRAPH_VERBOSITY=10`) and attach the full output. Cause: converting <bound method Dense.call of <tensorflow.python.layers.core.Dense object at 0x7f9f4cef41d0>>: AssertionError: Bad argument number for Name: 3, expecting 4
WARNING:tensorflow:Entity <bound method Dense.call of <tensorflow.python.layers.core.Dense object at 0x7f9f45d352b0>> could not be transformed and will be executed as-is. Please report this to the AutgoGraph team. When filing the bug, set the verbosity to 10 (on Linux, `export AUTOGRAPH_VERBOSITY=10`) and attach the full output. Cause: converting <bound method Dense.call of <tensorflow.python.layers.core.Dense object at 0x7f9f45d352b0>>: AssertionError: Bad argument number for Name: 3, expecting 4
W0609 10:11:05.918199 140324213704512 ag_logging.py:145] Entity <bound method Dense.call of <tensorflow.python.layers.core.Dense object at 0x7f9f45d352b0>> could not be transformed and will be executed as-is. Please report this to the AutgoGraph team. When filing the bug, set the verbosity to 10 (on Linux, `export AUTOGRAPH_VERBOSITY=10`) and attach the full output. Cause: converting <bound method Dense.call of <tensorflow.python.layers.core.Dense object at 0x7f9f45d352b0>>: AssertionError: Bad argument number for Name: 3, expecting 4
WARNING:tensorflow:Entity <bound method Conv2DTranspose.call of <tensorflow.python.layers.convolutional.Conv2DTranspose object at 0x7f9f45cfc828>> could not be transformed and will be executed as-is. Please report this to the AutgoGraph team. When filing the bug, set the verbosity to 10 (on Linux, `export AUTOGRAPH_VERBOSITY=10`) and attach the full output. Cause: converting <bound method Conv2DTranspose.call of <tensorflow.python.layers.convolutional.Conv2DTranspose object at 0x7f9f45cfc828>>: AttributeError: module 'gast' has no attribute 'Num'
W0609 10:11:05.951597 140324213704512 ag_logging.py:145] Entity <bound method Conv2DTranspose.call of <tensorflow.python.layers.convolutional.Conv2DTranspose object at 0x7f9f45cfc828>> could not be transformed and will be executed as-is. Please report this to the AutgoGraph team. When filing the bug, set the verbosity to 10 (on Linux, `export AUTOGRAPH_VERBOSITY=10`) and attach the full output. Cause: converting <bound method Conv2DTranspose.call of <tensorflow.python.layers.convolutional.Conv2DTranspose object at 0x7f9f45cfc828>>: AttributeError: module 'gast' has no attribute 'Num'
WARNING:tensorflow:Entity <bound method Conv2DTranspose.call of <tensorflow.python.layers.convolutional.Conv2DTranspose object at 0x7f9f45cfc828>> could not be transformed and will be executed as-is. Please report this to the AutgoGraph team. When filing the bug, set the verbosity to 10 (on Linux, `export AUTOGRAPH_VERBOSITY=10`) and attach the full output. Cause: converting <bound method Conv2DTranspose.call of <tensorflow.python.layers.convolutional.Conv2DTranspose object at 0x7f9f45cfc828>>: AttributeError: module 'gast' has no attribute 'Num'
W0609 10:11:05.998636 140324213704512 ag_logging.py:145] Entity <bound method Conv2DTranspose.call of <tensorflow.python.layers.convolutional.Conv2DTranspose object at 0x7f9f45cfc828>> could not be transformed and will be executed as-is. Please report this to the AutgoGraph team. When filing the bug, set the verbosity to 10 (on Linux, `export AUTOGRAPH_VERBOSITY=10`) and attach the full output. Cause: converting <bound method Conv2DTranspose.call of <tensorflow.python.layers.convolutional.Conv2DTranspose object at 0x7f9f45cfc828>>: AttributeError: module 'gast' has no attribute 'Num'
WARNING:tensorflow:Entity <bound method Conv2DTranspose.call of <tensorflow.python.layers.convolutional.Conv2DTranspose object at 0x7f9f4cf30128>> could not be transformed and will be executed as-is. Please report this to the AutgoGraph team. When filing the bug, set the verbosity to 10 (on Linux, `export AUTOGRAPH_VERBOSITY=10`) and attach the full output. Cause: converting <bound method Conv2DTranspose.call of <tensorflow.python.layers.convolutional.Conv2DTranspose object at 0x7f9f4cf30128>>: AttributeError: module 'gast' has no attribute 'Num'
W0609 10:11:06.045332 140324213704512 ag_logging.py:145] Entity <bound method Conv2DTranspose.call of <tensorflow.python.layers.convolutional.Conv2DTranspose object at 0x7f9f4cf30128>> could not be transformed and will be executed as-is. Please report this to the AutgoGraph team. When filing the bug, set the verbosity to 10 (on Linux, `export AUTOGRAPH_VERBOSITY=10`) and attach the full output. Cause: converting <bound method Conv2DTranspose.call of <tensorflow.python.layers.convolutional.Conv2DTranspose object at 0x7f9f4cf30128>>: AttributeError: module 'gast' has no attribute 'Num'
WARNING:tensorflow:Entity <bound method Conv2DTranspose.call of <tensorflow.python.layers.convolutional.Conv2DTranspose object at 0x7f9f4cf30128>> could not be transformed and will be executed as-is. Please report this to the AutgoGraph team. When filing the bug, set the verbosity to 10 (on Linux, `export AUTOGRAPH_VERBOSITY=10`) and attach the full output. Cause: converting <bound method Conv2DTranspose.call of <tensorflow.python.layers.convolutional.Conv2DTranspose object at 0x7f9f4cf30128>>: AttributeError: module 'gast' has no attribute 'Num'
W0609 10:11:06.094269 140324213704512 ag_logging.py:145] Entity <bound method Conv2DTranspose.call of <tensorflow.python.layers.convolutional.Conv2DTranspose object at 0x7f9f4cf30128>> could not be transformed and will be executed as-is. Please report this to the AutgoGraph team. When filing the bug, set the verbosity to 10 (on Linux, `export AUTOGRAPH_VERBOSITY=10`) and attach the full output. Cause: converting <bound method Conv2DTranspose.call of <tensorflow.python.layers.convolutional.Conv2DTranspose object at 0x7f9f4cf30128>>: AttributeError: module 'gast' has no attribute 'Num'
INFO:tensorflow:Done calling model_fn.
I0609 10:11:06.129676 140324213704512 estimator.py:1147] Done calling model_fn.
INFO:tensorflow:Starting evaluation at 2020-06-09T10:11:06Z
I0609 10:11:06.148515 140324213704512 evaluation.py:255] Starting evaluation at 2020-06-09T10:11:06Z
INFO:tensorflow:Graph was finalized.
I0609 10:11:06.373874 140324213704512 monitored_session.py:240] Graph was finalized.
2020-06-09 10:11:06.380528: I tensorflow/core/common_runtime/gpu/gpu_device.cc:1640] Found device 0 with properties: 
name: GeForce GTX 1080 Ti major: 6 minor: 1 memoryClockRate(GHz): 1.62
pciBusID: 0000:81:00.0
2020-06-09 10:11:06.380603: I tensorflow/stream_executor/platform/default/dso_loader.cc:42] Successfully opened dynamic library libcudart.so.10.0
2020-06-09 10:11:06.380625: I tensorflow/stream_executor/platform/default/dso_loader.cc:42] Successfully opened dynamic library libcublas.so.10.0
2020-06-09 10:11:06.380641: I tensorflow/stream_executor/platform/default/dso_loader.cc:42] Successfully opened dynamic library libcufft.so.10.0
2020-06-09 10:11:06.380658: I tensorflow/stream_executor/platform/default/dso_loader.cc:42] Successfully opened dynamic library libcurand.so.10.0
2020-06-09 10:11:06.380674: I tensorflow/stream_executor/platform/default/dso_loader.cc:42] Successfully opened dynamic library libcusolver.so.10.0
2020-06-09 10:11:06.380690: I tensorflow/stream_executor/platform/default/dso_loader.cc:42] Successfully opened dynamic library libcusparse.so.10.0
2020-06-09 10:11:06.380827: I tensorflow/stream_executor/platform/default/dso_loader.cc:53] Could not dlopen library 'libcudnn.so.7'; dlerror: libcudnn.so.7: cannot open shared object file: No such file or directory
2020-06-09 10:11:06.380838: W tensorflow/core/common_runtime/gpu/gpu_device.cc:1663] Cannot dlopen some GPU libraries. Skipping registering GPU devices...
2020-06-09 10:11:06.380852: I tensorflow/core/common_runtime/gpu/gpu_device.cc:1181] Device interconnect StreamExecutor with strength 1 edge matrix:
2020-06-09 10:11:06.380860: I tensorflow/core/common_runtime/gpu/gpu_device.cc:1187]      0 
2020-06-09 10:11:06.380866: I tensorflow/core/common_runtime/gpu/gpu_device.cc:1200] 0:   N 
INFO:tensorflow:Restoring parameters from 3dshapes_models/vae3dshapes_model_s1000_1602/metrics/reconstruction/tf_checkpoint/model.ckpt-5
I0609 10:11:06.382376 140324213704512 saver.py:1280] Restoring parameters from 3dshapes_models/vae3dshapes_model_s1000_1602/metrics/reconstruction/tf_checkpoint/model.ckpt-5
INFO:tensorflow:Running local_init_op.
I0609 10:11:06.443644 140324213704512 session_manager.py:500] Running local_init_op.
INFO:tensorflow:Done running local_init_op.
I0609 10:11:06.455898 140324213704512 session_manager.py:502] Done running local_init_op.
INFO:tensorflow:Finished evaluation at 2020-06-09-10:11:06
I0609 10:11:06.694937 140324213704512 evaluation.py:275] Finished evaluation at 2020-06-09-10:11:06
INFO:tensorflow:Saving dict for global step 5: global_step = 5, loss = 1955.4744, reconstruction_loss = 1955.4744
I0609 10:11:06.695150 140324213704512 estimator.py:2039] Saving dict for global step 5: global_step = 5, loss = 1955.4744, reconstruction_loss = 1955.4744
INFO:tensorflow:Saving 'checkpoint_path' summary for global step 5: 3dshapes_models/vae3dshapes_model_s1000_1602/metrics/reconstruction/tf_checkpoint/model.ckpt-5
I0609 10:11:06.744781 140324213704512 estimator.py:2099] Saving 'checkpoint_path' summary for global step 5: 3dshapes_models/vae3dshapes_model_s1000_1602/metrics/reconstruction/tf_checkpoint/model.ckpt-5
INFO:tensorflow:evaluation_loop marked as finished
I0609 10:11:06.745366 140324213704512 error_handling.py:96] evaluation_loop marked as finished
